File: First Draft/VSM/powderVSM.csv
Comment,Time Stamp (sec),Temperature (K),Magnetic Field (Oe),Moment (emu),M. Std. Err. (emu),Transport Action,Averaging Time (sec),Frequency (Hz),Peak Amplitude (mm),Center Position (mm),Coil Signal' (mV),Coil Signal" (mV),Range (mV),M. Quad. Signal (emu),M. Raw' (emu),M. Raw" (emu),Min. Temperature (K),Max. Temperature (K),Min. Field (Oe),Max. Field (Oe),Mass (grams),Motor Lag (deg),Pressure (Torr),VSM Status (code),Motor Status (code),Measure Status (code),Measure Count,System Temp. (K),Temp. Status (code),Field Status (code),Chamber Status (code),Motor Current (amps),Motor Heatsink Temp. (C),Map 01,Map 02,Map 03,Map 04,Map 05,Map 06,Map 07,Map 08,Map 09,Map 10,Map 11,Map 12,Map 13,Map 14,Map 15,Map 16
,3790608213.745,55.0254230499268,24.968297958374,-3.05464607960974E-6,1.73011184693602E-7,1,20.0100484152476,40.0298881530762,1.99248022256269,13.6599997058511,-1.65280433643426E-5,-3.31003943508918E-6,0.25,7.21609944629751E-8,-2.98480467276305E-6,-5.78021214956268E-8,55.0302772521973,55.0302772521973,24.968297958374,24.968297958374,59.2419703580639,19.990664972528,2.21856045722961,0,0,0,801,55.0204124450684,1,4,1,2.18048095703125,46.4320640563965,,,,,,,,,,,,,,,,
,3790609974.616,66.0606346130371,24.8614110946655,2.56173954472139E-7,1.10316553724259E-6,1,20.0100484152476,40.0298881530762,1.99161007132909,13.6599997058511,1.02309340836201E-6,2.04219119542941E-6,0.25,3.18471528595595E-7,2.42572457389699E-7,3.2395668658982E-7,66.0742568969727,66.0742568969727,24.8567638397217,24.8660583496094,60.0837842732756,19.9248986234401,2.27158498764038,0,0,0,801,66.0470123291016,1,4,1,2.17498779296875,55.2297172546387,,,,,,,,,,,,,,,,
,3790611735.58,77.0759048461914,24.8869705200195,1.47329095533998E-6,2.26705017144814E-7,1,20.0100484152476,40.0298881530762,1.99148546162212,13.6599997058511,8.30813382688928E-6,7.69082318001122E-7,0.25,-1.66838415286541E-7,1.47297959434056E-6,-1.26965030825818E-7,77.0920562744141,77.0920562744141,24.8846473693848,24.8892936706543,60.024380505814,19.9278398204815,2.32118821144104,0,0,0,801,77.0597534179688,1,4,1,2.18231201171875,55.7184753417969,,,,,,,,,,,,,,,,
,3790613496.444,88.0842666625977,25.00315284729,2.10451444843235E-6,2.67424782184214E-7,1,20.0100484152476,40.0298881530762,1.99136932629357,13.6599997058511,1.15670558093167E-5,2.74734432573543E-6,0.25,7.15022998644929E-8,2.10357146505354E-6,1.15609256878403E-7,88.1082916259766,88.1082916259766,24.9961814880371,25.010124206543,60.1939938944871,19.9274988734814,2.36239767074585,0,0,0,801,88.0602416992188,1,4,1,2.17498779296875,55.7184753417969,,,,,,,,,,,,,,,,
,3790615257.357,99.0770645141602,24.9102067947388,1.99651351019054E-6,2.85350527990852E-7,1,20.0100484152476,40.0298881530762,1.9911043207443,13.6599997058511,1.0863464936073E-5,3.25965468326835E-6,0.25,1.92978365932159E-7,1.99722772608682E-6,2.27094244719902E-7,99.1045837402344,99.1045837402344,24.9078826904297,24.9125308990479,60.2182243785833,19.9280632615366,2.39718508720398,0,0,0,801,99.0487899780273,1,4,1,2.16995239257813,55.7184753417969,,,,,,,,,,,,,,,,
,3790616838.189,110.138259887695,25.0054759979248,1.7353524818275E-6,2.61257879098206E-7,1,20.0100484152476,40.0298881530762,1.99122014096937,13.6700002476573,9.62926345028598E-6,1.93344384200089E-6,0.25,1.02514783683526E-8,1.7401797004446E-6,3.45700774677274E-8,110.173919677734,110.173919677734,25.0054759979248,25.0054759979248,59.7351779536986,19.9265777292113,2.42745184898376,0,0,0,801,110.102600097656,1,4,1,2.17910766601562,56.2072334289551,,,,,,,,,,,,,,,,
,3790618379.024,121.124069213867,24.8800001144409,1.54225957499733E-6,2.76583173360307E-7,1,20.0100484152476,40.0298881530762,1.99110310527493,13.6700002476573,8.44219610626246E-6,2.33518267110855E-6,0.25,1.23189906167821E-7,1.5458610692941E-6,1.41952532425059E-7,121.140472412109,121.140472412109,24.8707065582275,24.8892936706543,59.9110443705256,19.936791442968,2.45355844497681,0,0,0,801,121.107666015625,1,4,1,2.174072265625,55.7184753417969,,,,,,,,,,,,,,,,
,3790619919.8715,132.105163574219,25.0403299331665,1.24276371768041E-6,2.66555397253455E-7,1,20.0100484152476,40.0298881530762,1.99082828540622,13.6599997058511,6.8512169988355E-6,1.63347135819127E-6,0.25,5.6536082449929E-8,1.24647896423793E-6,6.95768001383903E-8,132.094268798828,132.094268798828,25.0380077362061,25.042652130127,60.1064515003333,19.9369705916078,2.47652673721313,0,0,0,801,132.116058349609,1,4,1,2.17941284179687,55.7184753417969,,,,,,,,,,,,,,,,
,3790621460.568,143.064956665039,24.9195022583008,1.10593567660855E-6,4.69660505966598E-7,1,20.0100484152476,40.0298881530762,1.99099086311785,13.6599997058511,5.87789009497919E-6,2.61361724496756E-6,0.25,2.60122148848665E-7,1.10741392673642E-6,2.71128983707807E-7,143.057861328125,143.057861328125,24.9125308990479,24.9264736175537,59.9571604531602,19.9441231549772,2.49825692176819,0,0,0,801,143.072052001953,1,4,1,2.17971801757813,55.7184753417969,,,,,,,,,,,,,,,,
,3790624625.194,55.0315895080566,29.3088474273682,-3.62483191509757E-6,7.0698302200232E-7,1,4.99626677034896,40.0298881530762,1.991417648344,13.6700002476573,-1.93585750756056E-5,-5.01342396308078E-6,0.25,-1.16546612527162E-7,-3.53350190192851E-6,-2.65934387924507E-7,55.0339775085449,55.0339775085449,16.807689666748,41.8100051879883,59.0067001737755,20.0060245869249,2.2468593120575,0,0,0,200,55.0285987854004,1,6,1,2.18673706054687,41.5444793701172,,,,,,,,,,,,,,,,
,3790624680.172,55.005054473877,302.916915893555,-2.85788175575115E-5,6.54796093119598E-7,1,4.99626677034896,40.0298881530762,1.99147768328831,13.6599997058511,-0.000153316912899518,-3.6473812934563E-5,0.25,-3.51130197870245E-7,-2.78824098225918E-5,-1.54253141126732E-6,55.0053825378418,55.0053825378418,290.476165771484,315.357666015625,58.9793431756024,20.0049741524355,2.24570560455322,0,0,0,200,55.0046730041504,1,6,1,2.18124389648438,44.9657897949219,,,,,,,,,,,,,,,,
,3790624735.094,54.9973564147949,576.336730957031,-4.21234324021075E-5,6.85500520673365E-7,1,4.99626677034896,40.0298881530762,1.99148026472504,13.6599997058511,-0.000226071995348425,-5.33844965926663E-5,0.25,-4.47909065783272E-7,-4.11011952405711E-5,-2.20518360690732E-6,54.9973297119141,54.9973297119141,563.837890625,588.835571289063,59.4561365723332,20.0045565713507,2.24433422088623,0,0,0,200,54.9970664978027,1,6,1,2.19039916992187,46.4320640563965,,,,,,,,,,,,,,,,
,3790624790.1415,54.9964656829834,850.827789306641,-3.79526260824512E-5,7.30220134052819E-7,1,4.99626677034896,40.0298881530762,1.99141652337272,13.6599997058511,-0.000202461465480501,-5.35649978749827E-5,0.25,-1.42019233539391E-6,-3.6990693763623E-5,-2.97871049992282E-6,54.9961242675781,54.9961242675781,838.347534179688,863.308044433594,59.465516114564,20.0024867161224,2.24333214759827,0,0,0,200,54.9964637756348,1,6,1,2.18734741210938,47.8983383178711,,,,,,,,,,,,,,,,
,3790624845.1525,54.9962406158447,1124.73559570312,-1.79783094015797E-5,7.73243597538066E-7,1,4.99626677034896,40.0298881530762,1.99127824342957,13.6599997058511,-9.56090261448997E-5,-2.66904048943156E-5,0.25,-9.17894706221938E-7,-1.7513263141328E-5,-1.6500731749597E-6,54.9960441589355,54.9960441589355,1112.26232910156,1137.20886230469,59.3623411500255,20.0023362624573,2.24256205558777,0,0,0,200,54.9967269897461,1,6,1,2.1893310546875,49.364616394043,,,,,,,,,,,,,,,,
,3790624900.0035,54.9970283508301,1397.34448242188,1.457905895878E-5,7.26144889915346E-7,1,4.99626677034896,40.0298881530762,1.99134886972079,13.6599997058511,7.94323370624072E-5,1.32249912505884E-5,0.25,-8.20468881121481E-7,1.42683279540786E-5,-1.89919753834021E-7,54.997200012207,54.997200012207,1384.59240722656,1410.09655761719,59.5147587112755,20.0009997630986,2.24176526069641,0,0,0,200,54.9968566894531,1,6,1,2.18597412109375,49.364616394043,,,,,,,,,,,,,,,,
,3790624954.98,54.9978561401367,1671.55670166016,5.48757009544739E-5,7.09672897398531E-7,1,4.99626677034896,40.0298881530762,1.99124092261297,13.6599997058511,0.000296932838969928,5.89040168687551E-5,0.25,-1.39102566987041E-6,5.3637993971598E-5,9.41024379400359E-7,54.9978561401367,54.9978561401367,1659.37622070313,1683.73718261719,59.668739529564,19.9980219788408,2.24159026145935,0,0,0,200,54.9978561401367,1,6,1,2.19131469726562,50.3421325683594,,,,,,,,,,,,,,,,
,3790625009.885,54.997579574585,1944.63952636719,0.00010145051330241,7.47968886819718E-7,1,4.99626677034896,40.0298881530762,1.99123530619625,13.6599997058511,0.000546994728799803,0.000117726366415139,0.25,-9.29596940938359E-7,9.90991406966522E-5,3.34089955712371E-6,54.997802734375,54.997802734375,1932.52404785156,1956.75500488281,59.7812940363332,19.9934250058248,2.24081707000732,0,0,0,200,54.9973564147949,1,6,1,2.177734375,51.3196487426758,,,,,,,,,,,,,,,,
,3790625064.9845,54.9976043701172,2218.71691894531,0.000151235878995994,7.93239792075032E-7,1,4.99626677034896,40.0298881530762,1.99122744487994,13.6599997058511,0.000815577972989553,0.000175021219419673,0.25,-1.47273411129066E-6,0.000147742935941707,4.89228590292795E-6,54.9975395202637,54.9975395202637,2206.52709960938,2230.90673828125,59.7547186666794,19.9862710941243,2.24040937423706,0,0,0,200,54.9976692199707,1,6,1,2.18170166015625,51.808406829834,,,,,,,,,,,,,,,,
,3790625119.8755,54.9979991912842,2491.830078125,0.000204361358025821,8.00241592177183E-7,1,4.99626677034896,40.0298881530762,1.99119088966499,13.6599997058511,0.00110142785018916,0.000239575302241719,0.25,-1.41577573190677E-6,0.000199629480062585,7.16717712679779E-6,54.9979591369629,54.9979591369629,2479.32202148438,2504.33813476562,59.6101173906217,19.9847738983138,2.23997497558594,0,0,0,200,54.9980392456055,1,6,1,2.18856811523438,51.808406829834,,,,,,,,,,,,,,,,
,3790625174.7845,54.9981708526611,2765.72631835938,0.000258941580600203,7.82993920939211E-7,1,4.99626677034896,40.0298881530762,1.99112688852052,13.6700002476573,0.00139524672737538,0.000305295515810551,0.25,-1.46665912892657E-6,0.000252947816906438,9.39519930912095E-6,54.9978561401367,54.9978561401367,2753.62255859375,2777.830078125,59.8219387193332,19.981716923625,2.23945951461792,0,0,0,200,54.9984855651855,1,6,1,2.18673706054687,52.7859268188477,,,,,,,,,,,,,,,,
,3790625229.798,54.9982757568359,3039.67578125,0.000315968687318784,1.59267968965771E-6,1,4.99626677034896,40.0298881530762,1.99108418256649,13.6700002476573,0.00170211858592924,0.000374658476232822,0.25,-1.38916844547087E-6,0.000308657483058927,1.18483363394332E-5,54.9982757568359,54.9982757568359,3027.42553710937,3051.92602539063,59.6515437021409,19.9775336487632,2.23900771141052,0,0,0,200,54.9982757568359,1,6,1,2.18963623046875,52.7859268188477,,,,,,,,,,,,,,,,
,3790625284.687,54.9985237121582,3312.99340820313,0.000373377615697675,8.26008880926516E-7,1,4.99626677034896,40.0298881530762,1.99107370336156,13.6599997058511,0.00201126060168871,0.000443799856943731,0.25,-1.43798331492455E-6,0.000364752732809986,1.41913491540097E-5,54.9986152648926,54.9986152648926,3300.53637695313,3325.45043945313,59.6742109291986,19.9772764423655,2.2387113571167,0,0,0,200,54.9984855651855,1,6,1,2.18093872070313,52.7859268188477,,,,,,,,,,,,,,,,
,3790625339.694,54.9986534118652,3586.90124511719,0.000431484624235787,9.76165354839336E-7,1,4.99626677034896,40.0298881530762,1.99113599885277,13.6599997058511,0.0023244219792236,0.000513180147601153,0.25,-1.6010236118016E-6,0.000421542137752161,1.64491383476187E-5,54.9987182617188,54.9987182617188,3574.44653320313,3599.35595703125,60.3417216846218,19.9694346546998,2.23814845085144,0,0,0,200,54.998405456543,1,6,1,2.18887329101562,53.2746849060059,,,,,,,,,,,,,,,,
,3790625394.7465,54.9989814758301,3860.90856933594,0.000491289289384893,1.40647722071344E-6,1,4.99626677034896,40.0298881530762,1.99095126850684,13.6599997058511,0.00264522516172686,0.000590072212129154,0.25,-7.35952229779738E-7,0.000479954897635498,1.97791235732208E-5,54.9990081787109,54.9990081787109,3848.45385742188,3873.36328125,60.0822210162371,19.9661048265439,2.2380313873291,0,0,0,200,54.9989547729492,1,6,1,2.18246459960938,53.2746849060059,,,,,,,,,,,,,,,,
,3790625449.6525,54.9984970092773,4134.35424804687,0.000550294284942156,9.41564179713905E-7,1,4.99626677034896,40.0298881530762,1.99091810511802,13.6599997058511,0.00296358082235263,0.000658673117129886,0.25,-1.23682101486735E-6,0.000537650783863805,2.17386805790943E-5,54.9980392456055,54.9980392456055,4121.6904296875,4147.01806640625,60.2807546601218,19.9684207834281,2.23772501945496,0,0,0,200,54.9987983703613,1,6,1,2.17758178710938,53.7634429931641,,,,,,,,,,,,,,,,
,3790625504.5515,54.9986019134521,4407.84838867188,0.000609773454969613,1.0167528380589E-6,1,4.99626677034896,40.0298881530762,1.99101522924988,13.6599997058511,0.0032850100623276,0.00072666949216816,0.25,-1.96286536389095E-6,0.000595827748834144,2.34947388259209E-5,54.9981956481934,54.9981956481934,4395.3681640625,4420.32861328125,60.413631508391,19.9660474878583,2.23739647865295,0,0,0,200,54.9986419677734,1,6,1,2.18368530273438,53.7634429931641,,,,,,,,,,,,,,,,
,3790625559.5345,54.9994659423828,4681.52880859375,0.000669730103952964,1.04831570888556E-6,1,4.99626677034896,40.0298881530762,1.99095788694137,13.6700002476573,0.00360699272014718,0.000803321389639969,0.25,-1.17647596194016E-6,0.000654417151776044,2.67449203128806E-5,54.9993743896484,54.9993743896484,4668.6884765625,4694.369140625,59.6820272143909,19.9618564515771,2.23701238632202,0,0,0,200,54.999324798584,1,6,1,2.18490600585938,54.2522010803223,,,,,,,,,,,,,,,,
,3790625614.541,54.9991931915283,4955.35986328125,0.00072956704400944,1.04393412506479E-6,1,4.99626677034896,40.0298881530762,1.99091767583299,13.6599997058511,0.00393068076934903,0.000869616694658507,0.25,-2.28598234981386E-6,0.00071297580247085,2.81348942332354E-5,54.9990882873535,54.9990882873535,4943.1513671875,4967.568359375,60.3088932868141,19.9612128094594,2.23704624176025,0,0,0,200,54.9992980957031,1,6,1,2.17864990234375,54.2522010803223,,,,,,,,,,,,,,,,
,3790625674.465,54.9986019134521,4821.69750976562,0.000708744217372146,1.08275803817533E-6,1,4.99626677034896,40.0298881530762,1.99073786348064,13.6700002476573,0.00381720610519918,0.000848366852783152,0.25,-1.54858596774714E-6,0.00069257496009727,2.79975836419382E-5,54.9987983703613,54.9987983703613,4809.263671875,4834.13134765625,59.7789491507756,19.9570640861177,2.23683857917786,0,0,0,200,54.9986953735352,1,6,1,2.17849731445313,54.7409591674805,,,,,,,,,,,,,,,,
,3790625729.475,54.9990863800049,4547.763671875,0.000653617589533214,9.66859356031078E-7,1,4.99626677034896,40.0298881530762,1.99105348510704,13.6599997058511,0.00352221409620024,0.00077532026925381,0.25,-2.77057737184905E-6,0.000638719257012858,2.45243850595477E-5,54.9989547729492,54.9989547729492,4535.29296875,4560.234375,59.7664430944679,19.954798878219,2.23650693893433,0,0,0,200,54.9987716674805,1,6,1,2.17544555664062,54.7409591674805,,,,,,,,,,,,,,,,
,3790625784.4425,54.9993495941162,4273.69555664063,0.000598080815874023,9.20956911515329E-7,1,4.99626677034896,40.0298881530762,1.99079442246304,13.6599997058511,0.00322060461202052,0.000716940360522216,0.25,-1.13343419569584E-6,0.000584351079485903,2.38246992952459E-5,54.9995079040527,54.9995079040527,4261.2060546875,4286.18505859375,59.780512407814,19.958179416392,2.23635268211365,0,0,0,200,54.9991912841797,1,6,1,2.17544555664062,54.7409591674805,,,,,,,,,,,,,,,,
,3790625839.4015,54.9992179870605,3999.75061035156,0.000541613258764976,9.125372586413E-7,1,4.99626677034896,40.0298881530762,1.99080872697904,13.6599997058511,0.00291696329895706,0.000646538419725995,0.25,-1.53819435490988E-6,0.000529165992365011,2.10884666953734E-5,54.9987182617188,54.9987182617188,3986.91479492188,4012.58642578125,59.9774827946602,19.9541262088309,2.23624300956726,0,0,0,200,54.9996910095215,1,6,1,2.17086791992187,54.7409591674805,,,,,,,,,,,,,,,,
,3790625894.223,54.9992446899414,3726.68420410156,0.00048523738614535,9.37849178542345E-7,1,4.99626677034896,40.0298881530762,1.99083870619439,13.6599997058511,0.00261299618114327,0.000580167781317156,0.25,-1.21359628352944E-6,0.000474047935893485,1.90655929459719E-5,54.9991912841797,54.9991912841797,3714.21801757812,3739.150390625,59.8094326630256,19.9532453982605,2.23594236373901,0,0,0,200,54.9992179870605,1,6,1,2.18841552734375,54.7409591674805,,,,,,,,,,,,,,,,
,3790625949.2425,54.9992179870605,3452.99926757812,0.000428468844483089,9.60215042439059E-7,1,4.99626677034896,40.0298881530762,1.99083374734893,13.6700002476573,0.00230683354010562,0.000513650488818324,0.25,-8.24489173053386E-7,0.000418551048530869,1.70865028275215E-5,54.9989547729492,54.9989547729492,3440.51196289063,3465.48657226562,60.0282886484102,19.9499867683548,2.23577451705933,0,0,0,200,54.9994812011719,1,6,1,2.16995239257813,55.2297172546387,,,,,,,,,,,,,,,,
,3790626004.225,54.9994411468506,3179.84436035156,0.000372416004130141,8.45879933303925E-7,1,4.99626677034896,40.0298881530762,1.99080902998403,13.6599997058511,0.00200582729328422,0.000442301072235466,0.25,-1.49186224280629E-6,0.000363804992249042,1.41025299173268E-5,54.9991912841797,54.9991912841797,3167.14575195313,3192.54296875,59.8289733760063,19.9494347085243,2.23552274703979,0,0,0,200,54.9996910095215,1,6,1,2.18734741210938,54.7409591674805,,,,,,,,,,,,,,,,
,3790626059.1885,54.9992580413818,2906.19689941406,0.000318653465369302,8.71567638153338E-7,1,4.99626677034896,40.0298881530762,1.99074359413868,13.6599997058511,0.00171522645857961,0.000382308438506666,0.25,-5.60932129152668E-7,0.000311235978982432,1.27727669250359E-5,54.9990081787109,54.9990081787109,2893.69116210937,2918.70263671875,60.1963387800448,19.9483991532701,2.23519706726074,0,0,0,200,54.9995079040527,1,6,1,2.1661376953125,55.2297172546387,,,,,,,,,,,,,,,,
,3790626114.162,54.9996643066406,2632.12658691406,0.000264338080328265,8.28942402106924E-7,1,4.99626677034896,40.0298881530762,1.99083639964109,13.6599997058511,0.00142418739043797,0.00031114314786474,0.25,-1.58609496186555E-6,0.000258215948518585,9.50685161469286E-6,54.9998207092285,54.9998207092285,2619.99487304687,2644.25830078125,59.7218902688717,19.9482965690792,2.23551440238953,0,0,0,200,54.9996643066406,1,6,1,2.18307495117187,55.2297172546387,,,,,,,,,,,,,,,,
,3790626169.171,54.9988117218018,2358.3837890625,0.000212560913046687,8.14887872241651E-7,1,4.99626677034896,40.0298881530762,1.99071348945575,13.6599997058511,0.00114456638218057,0.000252481054029352,0.25,-8.50750997334441E-7,0.000207607301330928,8.06413372486215E-6,54.9985618591309,54.9985618591309,2345.8291015625,2370.9384765625,59.9946786220833,19.9473795537403,2.23495602607727,0,0,0,200,54.9990615844727,1,6,1,2.18460083007813,55.2297172546387,,,,,,,,,,,,,,,,
,3790626224.1235,55.0000705718994,2084.84301757813,0.000162317388231229,8.40341309070932E-7,1,4.99626677034896,40.0298881530762,1.99075497023703,13.6599997058511,0.000873751121945143,0.000193860640219849,0.25,-4.55231031463194E-7,0.000158517409411935,6.35116419063243E-6,55.0000839233398,55.0000839233398,2072.68579101562,2097.00024414062,59.7539370381602,19.9469882418016,2.23504257202148,0,0,0,200,55.0001373291016,1,6,1,2.1795654296875,55.2297172546387,,,,,,,,,,,,,,,,
,3790626279.0005,54.9995975494385,1811.94366455078,0.000114267114131244,7.40010678223215E-7,1,4.99626677034896,40.0298881530762,1.99066673554527,13.6599997058511,0.000615704808838394,0.000133482088245819,0.25,-8.76579568633421E-7,0.000111608772656678,3.93042126982641E-6,54.9994010925293,54.9994010925293,1799.46337890625,1824.42395019531,59.7812940363332,19.9449186900099,2.23509836196899,0,0,0,200,54.9996643066406,1,6,1,2.176513671875,55.2297172546387,,,,,,,,,,,,,,,,
,3790626334.016,54.9994411468506,1537.59448242187,7.15916599512251E-5,8.09119548724197E-7,1,4.99626677034896,40.0298881530762,1.99062916099091,13.6599997058511,0.000385271080099418,8.56574540281395E-5,0.25,-1.72798911661796E-7,6.99063849218244E-5,2.83147710230789E-6,54.9992446899414,54.9992446899414,1525.42321777344,1549.76574707031,59.7312698111025,19.9437489077477,2.23471570014954,0,0,0,200,54.9995574951172,1,6,1,2.18368530273438,55.2297172546387,,,,,,,,,,,,,,,,
,3790626388.989,54.9989433288574,1263.99798583984,3.43650440769525E-5,7.47788888091008E-7,1,4.99626677034896,40.0298881530762,1.99076999934469,13.6599997058511,0.000185889016140631,3.6890358269069E-5,0.25,-8.69601012293578E-7,3.35872080454533E-5,5.91800575825947E-7,54.9986953735352,54.9986953735352,1251.51306152344,1276.48291015625,59.5085056831217,19.9457764465319,2.23472166061401,0,0,0,200,54.9990615844727,1,6,1,2.18399047851562,55.2297172546387,,,,,,,,,,,,,,,,
,3790626443.924,54.9993495941162,990.664093017578,5.10812482383804E-6,6.73539822419492E-7,1,4.99626677034896,40.0298881530762,1.99069862885994,13.6700002476573,2.77700825503283E-5,4.85463995927178E-6,0.25,-2.46205683263493E-7,4.99715387566458E-6,-2.61036606361189E-8,54.9993743896484,54.9993743896484,977.825988769531,1003.50219726562,59.8524222315833,19.9421675010727,2.23468804359436,0,0,0,200,54.9995346069336,1,6,1,2.17453002929687,55.2297172546387,,,,,,,,,,,,,,,,
,3790626498.806,54.9976844787598,717.650939941406,-1.2568150529031E-5,6.98486979163881E-7,1,4.99626677034896,40.0298881530762,1.99063713313564,13.6599997058511,-6.74571754130078E-5,-1.57824331380388E-5,0.25,-1.0783131223684E-7,-1.22645403503239E-5,-6.32650521973892E-7,54.997932434082,54.997932434082,705.15673828125,730.145141601562,59.9141708846025,19.9425907083365,2.23461055755615,0,0,0,200,54.9974365234375,1,6,1,2.17376708984375,55.2297172546387,,,,,,,,,,,,,,,,
,3790626553.84,54.9993095397949,443.863967895508,-1.63723191468764E-5,6.52976394295616E-7,1,4.99626677034896,40.0298881530762,1.99061376336895,13.6700002476573,-8.83847478491935E-5,-1.8272535421655E-5,0.25,2.84898118256187E-7,-1.59939675157274E-5,-4.09154099880062E-7,54.999137878418,54.999137878418,431.125793457031,456.602142333984,59.966539995391,19.9411995429795,2.23483180999756,0,0,0,200,54.999454498291,1,6,1,2.171630859375,55.7184753417969,,,,,,,,,,,,,,,,
,3790626608.783,54.9996242523193,170.22338104248,-5.14717507326536E-6,6.83367960228758E-7,1,4.99626677034896,40.0298881530762,1.99058056295434,13.6700002476573,-2.82447772197557E-5,-3.70095212750048E-6,0.25,4.6965119260765E-7,-5.04398788202195E-6,2.4230339916407E-7,54.9993743896484,54.9993743896484,157.764053344727,182.682708740234,59.7617533233525,19.9440283467134,2.23458504676819,0,0,0,200,54.9998741149902,1,6,1,2.17437744140625,55.2297172546387,,,,,,,,,,,,,,,,
,3790626663.728,54.9993629455566,-103.305667877197,1.84260908196499E-5,7.24279244607032E-7,1,4.99626677034896,40.0298881530762,1.99049037311588,13.6599997058511,9.75014901343515E-5,2.92731697536555E-5,0.25,1.29907575482323E-6,1.79313859801643E-5,2.0418230359923E-6,54.9995346069336,54.9995346069336,-115.495460510254,-91.1158752441406,59.9751379091025,19.9433423284058,2.2344913482666,0,0,0,200,54.9996376037598,1,6,1,2.17727661132813,56.2072334289551,,,,,,,,,,,,,,,,
,3790626718.6815,54.9994945526123,-376.799865722656,3.75776655137455E-5,6.98658904134746E-7,1,4.99626677034896,40.0298881530762,1.9906984531106,13.6700002476573,0.000201188787228382,4.93988072273927E-5,0.25,7.32916778818351E-7,3.66506805936272E-5,2.29296543334346E-6,54.9996643066406,54.9996643066406,-388.680633544922,-364.919097900391,59.8070877774679,19.9368715810587,2.23454332351685,0,0,0,200,54.9992980957031,1,6,1,2.1795654296875,55.7184753417969,,,,,,,,,,,,,,,,
,3790626773.6515,54.9993495941162,-650.1708984375,4.51737410699497E-5,7.44449209764874E-7,1,4.99626677034896,40.0298881530762,1.99072866898253,13.6599997058511,0.000240948788254536,6.34925772214468E-5,0.25,1.64510655680847E-6,4.40292963413215E-5,3.50166717024808E-6,54.999324798584,54.999324798584,-662.311889648438,-638.029907226563,59.8360080326794,19.9440473762057,2.23442578315735,0,0,0,200,54.9993743896484,1,6,1,2.19070434570313,55.7184753417969,,,,,,,,,,,,,,,,
,3790626828.664,54.9996376037598,-924.073974609375,3.62826996691344E-5,7.31667843106534E-7,1,4.99626677034896,40.0298881530762,1.99072885513485,13.6599997058511,0.000193365557345926,5.17524152279996E-5,0.25,1.46219526586541E-6,3.53593691260123E-5,2.9494504289251E-6,54.9998741149902,54.9998741149902,-937.160705566406,-910.987243652344,60.2229141496987,19.9410342953534,2.2342312335968,0,0,0,200,54.9994010925293,1,6,1,2.18399047851562,55.7184753417969,,,,,,,,,,,,,,,,
,3790626883.5655,54.9996776580811,-1197.52642822266,1.21308028433491E-5,7.87901561333542E-7,1,4.99626677034896,40.0298881530762,1.99063170042328,13.6599997058511,6.26314235348164E-5,2.62803986021394E-5,0.25,2.1583313247055E-6,1.17527183683304E-5,2.61581188147316E-6,54.9996376037598,54.9996376037598,-1210.099609375,-1184.95324707031,59.9954602506025,19.9403388088199,2.23449373245239,0,0,0,200,54.9997177124023,1,6,1,2.17117309570313,55.7184753417969,,,,,,,,,,,,,,,,
,3790626938.5045,54.9995975494385,-1470.9833984375,-2.2784082895198E-5,8.07751962645671E-7,1,4.99626677034896,40.0298881530762,1.99067622937389,13.6700002476573,-0.000124286203438546,-1.98242474623311E-5,0.25,1.43772304776125E-6,-2.23054007818243E-5,4.48797763237488E-7,54.9992179870605,54.9992179870605,-1483.84704589844,-1458.11975097656,59.7594084377948,19.9402899320414,2.23436498641968,0,0,0,200,54.9995079040527,1,6,1,2.17376708984375,55.7184753417969,,,,,,,,,,,,,,,,
,3790626993.5145,55.0066146850586,-1745.08648681641,-6.47368450628677E-5,7.27340862306066E-7,1,4.99626677034896,40.0298881530762,1.99058392649785,13.6700002476573,-0.000350858824395503,-6.64893915411909E-5,0.25,2.1941449600749E-6,-6.33016984345865E-5,-5.69324101758107E-7,55.0112838745117,55.0112838745117,-1757.27856445313,-1732.89440917969,59.6531069591794,19.9383191413455,2.23413348197937,0,0,0,200,55.0010261535645,1,6,1,2.17819213867187,55.2297172546387,,,,,,,,,,,,,,,,
,3790627048.5385,54.9989681243897,-2019.03601074219,-0.000112736812751587,7.85828669390684E-7,1,4.99626677034896,40.0298881530762,1.9906364453083,13.6599997058511,-0.000608944484145249,-0.000125164811280485,0.25,2.07744586573419E-6,-0.000110169561487661,-2.69200171040061E-6,54.9987449645996,54.9987449645996,-2031.42102050781,-2006.65100097656,60.3886193957756,19.9369824149082,2.23424863815308,0,0,0,200,54.9990615844727,1,6,1,2.17666625976562,55.7184753417969,,,,,,,,,,,,,,,,
,3790627103.4685,54.9996242523193,-2292.27014160156,-0.000164314984818383,7.94135031162757E-7,1,4.99626677034896,40.0298881530762,1.9906202427301,13.6599997058511,-0.000886033136028814,-0.00018935277071249,0.25,1.73856768208767E-6,-0.000160528828211271,-5.17902385030644E-6,54.999454498291,54.999454498291,-2304.38793945313,-2280.15234375,60.0658068173333,19.9369344032357,2.23460483551025,0,0,0,200,54.999927520752,1,6,1,2.17117309570313,55.7184753417969,,,,,,,,,,,,,,,,
,3790627158.414,54.9994678497314,-2565.73168945313,-0.000217553741752475,8.47824123851718E-7,1,4.99626677034896,40.0298881530762,1.99055874200193,13.6700002476573,-0.00117344676134599,-0.000249371270453366,0.25,2.54565209984075E-6,-0.00021256380998722,-6.61422896989453E-6,54.999454498291,54.999454498291,-2578.20971679687,-2553.25366210938,59.8782159727179,19.9401443451793,2.23420023918152,0,0,0,200,54.999324798584,1,6,1,2.17575073242187,55.2297172546387,,,,,,,,,,,,,,,,
,3790627213.358,54.9995861053467,-2839.23754882813,-0.000272745226978091,8.45870356022991E-7,1,4.99626677034896,40.0298881530762,1.99054583488179,13.6700002476573,-0.00147006619804635,-0.000317783935073788,0.25,2.23066434307938E-6,-0.000266465631595574,-9.22439186624359E-6,54.9996376037598,54.9996376037598,-2851.11596679687,-2827.35913085938,59.976701166141,19.9414544787435,2.23414254188538,0,0,0,200,54.9995346069336,1,6,1,2.17666625976562,55.7184753417969,,,,,,,,,,,,,,,,
,3790627268.3065,54.9996643066406,-3112.96398925781,-0.000330105502336075,8.25916115766869E-7,1,4.99626677034896,40.0298881530762,1.99048938309583,13.6700002476573,-0.00177824125306339,-0.000389305688399143,0.25,1.82217533767491E-6,-0.000322488804828499,-1.20139715028443E-5,54.9995346069336,54.9995346069336,-3125.16064453125,-3100.76733398438,60.1181759281218,19.9390179725266,2.2342369556427,0,0,0,200,54.9997940063477,1,6,1,2.17132568359375,55.7184753417969,,,,,,,,,,,,,,,,
,3790627323.283,54.9995079040527,-3386.76049804687,-0.000388155650591039,8.84285548025371E-7,1,4.99626677034896,40.0298881530762,1.99062236722452,13.6599997058511,-0.00209154658416767,-0.000456357437608052,0.25,2.40523906587804E-6,-0.000379234519382905,-1.38612198012377E-5,54.9997177124023,54.9997177124023,-3398.95971679687,-3374.56127929687,60.0916005584679,19.9378174077255,2.23426795005798,0,0,0,200,54.9992980957031,1,6,1,2.18475341796875,55.7184753417969,,,,,,,,,,,,,,,,
,3790627378.346,54.9998359680176,-3661.04699707031,-0.000446167265170693,8.60093696033904E-7,1,4.99626677034896,40.0298881530762,1.99056701124625,13.6599997058511,-0.00240315257938392,-0.000529360394150308,0.25,1.86472567994935E-6,-0.000435903614581662,-1.68013643012279E-5,55.0001640319824,55.0001640319824,-3672.5537109375,-3649.54028320313,59.9071362279294,19.9397842374332,2.23442077636719,0,0,0,200,54.9995079040527,1,6,1,2.18460083007813,55.7184753417969,,,,,,,,,,,,,,,,
,3790627433.146,54.9998874664307,-3933.89282226562,-0.000505114498291287,9.34948529325183E-7,1,4.99626677034896,40.0298881530762,1.99051931795002,13.6599997058511,-0.00272075483577829,-0.000599371510885673,0.25,2.08862057433772E-6,-0.000493526018931877,-1.90310964393405E-5,55.0000839233398,55.0000839233398,-3946.41259765625,-3921.373046875,59.9813909372563,19.9416949021971,2.23425722122192,0,0,0,200,54.9996910095215,1,6,1,2.17803955078125,56.2072334289551,,,,,,,,,,,,,,,,
,3790627488.1125,54.9998073577881,-4208.1767578125,-0.000564975519419538,1.02447092137905E-6,1,4.99626677034896,40.0298881530762,1.99056304360114,13.6599997058511,-0.00304282497976174,-0.000673257979311929,0.25,1.80098536333787E-6,-0.000552027805411981,-2.17956236673524E-5,54.9997940063477,54.9997940063477,-4220.60595703125,-4195.74755859375,60.0486109899102,19.9384733105101,2.23442649841309,0,0,0,200,54.9998207092285,1,6,1,2.17453002929687,55.7184753417969,,,,,,,,,,,,,,,,
,3790627543.0645,54.9996910095215,-4481.48291015625,-0.000624509478147324,9.50000381547567E-7,1,4.99626677034896,40.0298881530762,1.99055852830986,13.6599997058511,-0.00336377317549696,-0.000743802051227455,0.25,2.05661563592861E-6,-0.000610240664278113,-2.4012757885763E-5,54.9999008178711,54.9999008178711,-4493.6796875,-4469.2861328125,60.044702847314,19.9405298396692,2.23439025878906,0,0,0,200,54.9994812011719,1,6,1,2.17529296875,56.2072334289551,,,,,,,,,,,,,,,,
,3790627598.008,54.9992179870605,-4754.60327148438,-0.000684829263530326,1.0159212035376E-6,1,4.99626677034896,40.0298881530762,1.99045093942699,13.6599997058511,-0.00368896890207912,-0.000814538039917489,0.25,2.44371182054272E-6,-0.000669234566133075,-2.61311623089735E-5,54.9992446899414,54.9992446899414,-4766.75830078125,-4742.4482421875,59.8063061489486,19.9404250750079,2.23434853553772,0,0,0,200,54.999324798584,1,6,1,2.1746826171875,55.7184753417969,,,,,,,,,,,,,,,,
,3790627662.2,54.9996643066406,-4998.02734375,-0.000739346274374537,9.30414544581171E-7,1,4.99626677034896,40.0298881530762,1.99056538759433,13.6599997058511,-0.00398223549024878,-0.000883319494205792,0.25,1.90661650968367E-6,-0.000722523747107719,-2.89095470735728E-5,54.9996643066406,54.9996643066406,-4998.3828125,-4997.671875,60.3159279434872,19.9384178103456,2.23463106155396,0,0,0,200,54.9996643066406,1,6,1,2.17422485351562,55.7184753417969,,,,,,,,,,,,,,,,
,3790627713.0165,55.0003852844238,-4745.2529296875,-0.000692627939974757,9.89458309447314E-7,1,4.99626677034896,40.0298881530762,1.99047063084262,13.6599997058511,-0.00373059434335256,-0.000825680635385974,0.25,2.12625136931277E-6,-0.000676840892715747,-2.67662538454821E-5,55.0006065368652,55.0006065368652,-4757.0732421875,-4733.4326171875,60.2807546601218,19.9418565975882,2.23441195487976,0,0,0,200,55.0000305175781,1,6,1,2.18276977539062,55.7184753417969,,,,,,,,,,,,,,,,
,3790627767.96,54.9997291564941,-4472.49072265625,-0.000637892937204874,1.01100553293908E-6,1,4.99626677034896,40.0298881530762,1.99059684757303,13.6700002476573,-0.00343544364511775,-0.000761862960322487,0.25,1.70954559209972E-6,-0.000623300703303424,-2.49100157560008E-5,54.9997940063477,54.9997940063477,-4484.9755859375,-4460.005859375,60.0837842732756,19.9395858382172,2.23443198204041,0,0,0,200,54.9998741149902,1,6,1,2.1697998046875,56.2072334289551,,,,,,,,,,,,,,,,
,3790627822.966,54.9995727539063,-4198.33178710937,-0.000581199387556558,9.95792924682396E-7,1,4.99626677034896,40.0298881530762,1.99054248092502,13.6599997058511,-0.00313067427135063,-0.00069030633804932,0.25,2.27628978454787E-6,-0.000567895971849592,-2.20082693401849E-5,54.999454498291,54.999454498291,-4211.1953125,-4185.46826171875,60.159602239641,19.9384617094525,2.23444414138794,0,0,0,200,54.9996910095215,1,6,1,2.17788696289062,55.7184753417969,,,,,,,,,,,,,,,,
,3790627877.877,55.0000305175781,-3925.07702636719,-0.000525131398525808,9.91893601255708E-7,1,4.99626677034896,40.0298881530762,1.99048537106555,13.6599997058511,-0.00282830836027123,-0.000624062819643784,0.25,1.99514226161854E-6,-0.000513075359928805,-1.99578059842254E-5,55.0000305175781,55.0000305175781,-3937.63403320313,-3912.52001953125,59.9688848809486,19.9374921012495,2.23469018936157,0,0,0,200,54.9996643066406,1,6,1,2.18032836914062,56.6959953308105,,,,,,,,,,,,,,,,
,3790627932.881,55.0001487731934,-3650.58349609375,-0.000468334035798653,8.98405952424787E-7,1,4.99626677034896,40.0298881530762,1.99044549007548,13.6599997058511,-0.00252227739698204,-0.000556139916721991,0.25,1.86230687391842E-6,-0.000457555574255253,-1.77293015532104E-5,55.0000305175781,55.0000305175781,-3662.81274414063,-3638.35424804687,59.9001015712563,19.9400530696529,2.23476886749268,0,0,0,200,55.0001106262207,1,6,1,2.176513671875,55.7184753417969,,,,,,,,,,,,,,,,
,3790627987.8455,54.9996128082275,-3377.48681640625,-0.000412791998253474,8.77327831156663E-7,1,4.99626677034896,40.0298881530762,1.990417914453,13.6700002476573,-0.00222330932007662,-0.000488663024753296,0.25,1.92819085643672E-6,-0.000403277531395527,-1.53563696927059E-5,54.9992980957031,54.9992980957031,-3389.71142578125,-3365.26220703125,59.8680548019679,19.9383479483535,2.23460817337036,0,0,0,200,54.999927520752,1,6,1,2.18475341796875,55.7184753417969,,,,,,,,,,,,,,,,
,3790628042.7545,54.9999923706055,-3104.34582519531,-0.000356812512530995,7.62491851097436E-7,1,4.99626677034896,40.0298881530762,1.99057106772798,13.6599997058511,-0.00192149187015445,-0.00042389324841811,0.25,1.39833240387824E-6,-0.00034855520074901,-1.35440985411608E-5,55.0000839233398,55.0000839233398,-3116.81909179687,-3091.87255859375,59.9407462542563,19.9356082093223,2.2346818447113,0,0,0,200,54.9999008178711,1,6,1,2.18185424804687,56.2072334289551,,,,,,,,,,,,,,,,
,3790628097.723,54.9994277954102,-2830.50061035156,-0.000302058316314427,7.87288883117833E-7,1,4.99626677034896,40.0298881530762,1.99040990452996,13.6700002476573,-0.00162690008419415,-0.000356579404972322,0.25,1.60332507724554E-6,-0.000295066919008199,-1.10628371441643E-5,54.9993743896484,54.9993743896484,-2842.91357421875,-2818.08764648438,59.7969266067178,19.9392821236716,2.23449563980103,0,0,0,200,54.9992179870605,1,6,1,2.18231201171875,56.2072334289551,,,,,,,,,,,,,,,,
,3790628152.6325,54.9998092651367,-2557.26904296875,-0.000248467754774338,8.22151502462167E-7,1,4.99626677034896,40.0298881530762,1.99046932803883,13.6599997058511,-0.00133837244480839,-0.000292618170616828,0.25,1.45300068501545E-6,-0.000242707594573992,-8.97453471312726E-6,54.9997177124023,54.9997177124023,-2569.69580078125,-2544.84228515625,60.0032765357948,19.9390667805938,2.23476910591126,0,0,0,200,54.9999008178711,1,6,1,2.1844482421875,56.2072334289551,,,,,,,,,,,,,,,,
,3790628207.6145,54.9996509552002,-2283.46105957031,-0.000196790389070825,7.57259042921716E-7,1,4.99626677034896,40.0298881530762,1.99050961057998,13.6700002476573,-0.00106003005393178,-0.000231480970292315,0.25,1.20543535383889E-6,-0.000192218877317186,-7.05889939913179E-6,54.9996643066406,54.9996643066406,-2295.70654296875,-2271.21557617187,59.8500773460256,19.9371313340298,2.23496294021606,0,0,0,200,54.9996376037598,1,6,1,2.17636108398438,56.2072334289551,,,,,,,,,,,,,,,,
,3790628262.597,54.999979019165,-2009.63690185547,-0.000148259083310199,8.10204940428163E-7,1,4.99626677034896,40.0298881530762,1.99050999804775,13.6599997058511,-0.000798804945544292,-0.000173320404894472,0.25,1.10947271201582E-6,-0.000144814910995791,-5.12460367371925E-6,54.9999008178711,54.9999008178711,-2022.4609375,-1996.81286621094,59.9782644231794,19.9409253037019,2.23488807678223,0,0,0,200,55.000057220459,1,6,1,2.18154907226562,55.7184753417969,,,,,,,,,,,,,,,,
,3790628317.489,54.999927520752,-1735.99865722656,-0.000101091290315001,7.60403655880497E-7,1,4.99626677034896,40.0298881530762,1.99054934594761,13.6599997058511,-0.000544754499688735,-0.000117706925553067,0.25,8.45873588578146E-7,-9.87409098181048E-5,-3.40905867260248E-6,55.0001373291016,55.0001373291016,-1748.42541503906,-1723.57189941406,60.1158310425641,19.9384429548251,2.2347948551178,0,0,0,200,55.000057220459,1,6,1,2.18307495117187,55.7184753417969,,,,,,,,,,,,,,,,
,3790628372.5185,55.0000591278076,-1462.06530761719,-5.94289795843838E-5,6.69673690003074E-7,1,4.99626677034896,40.0298881530762,1.99037918265931,13.6599997058511,-0.00032186126428404,-6.18131433524158E-5,0.25,1.86980741208317E-6,-5.81015387222677E-5,-6.65208481122119E-7,55.0001640319824,55.0001640319824,-1474.61755371094,-1449.51306152344,59.709384212564,19.9364818557969,2.2346932888031,0,0,0,200,54.9999542236328,1,6,1,2.1826171875,55.7184753417969,,,,,,,,,,,,,,,,
,3790628427.412,54.9999256134033,-1189.05212402344,-2.40787268286678E-5,7.47376152198333E-7,1,4.99626677034896,40.0298881530762,1.99041949226184,13.6599997058511,-0.000129985973610863,-2.6900975041403E-5,0.25,4.12770085522164E-7,-2.35251704669984E-5,-6.06654502420262E-7,55.000057220459,55.000057220459,-1201.55334472656,-1176.55090332031,60.4933576173526,19.9372655791556,2.23486137390137,0,0,0,200,54.999927520752,1,6,1,2.18307495117187,55.7184753417969,,,,,,,,,,,,,,,,
,3790628482.5425,54.9995193481445,-914.881713867187,2.42652793597801E-6,9.04547975209193E-7,1,4.99626677034896,40.0298881530762,1.99046266307721,13.6599997058511,1.2066795926154E-5,7.29976059166201E-6,0.25,8.11712854966297E-7,2.33482430395552E-6,8.94216946093854E-7,54.9996643066406,54.9996643066406,-927.271301269531,-902.492126464844,59.8235019763717,19.9392221594608,2.23514533042908,0,0,0,200,54.9993743896484,1,6,1,2.17514038085938,56.2072334289551,,,,,,,,,,,,,,,,
,3790628537.378,55.0000324249268,-641.759368896484,1.64325013404157E-5,7.02393430545278E-7,1,4.99626677034896,40.0298881530762,1.99041647275072,13.6700002476573,8.76804944578213E-5,2.28889316383006E-5,0.25,5.60534900502811E-7,1.60177795166726E-5,1.23678553161467E-6,54.999927520752,54.999927520752,-654.258239746094,-629.260498046875,59.9946786220833,19.9397026828683,2.23493623733521,0,0,0,200,55.000057220459,1,6,1,2.18765258789062,55.7184753417969,,,,,,,,,,,,,,,,
,3790628592.4395,54.9998226165771,-367.846893310547,1.64514991459728E-5,6.63508414107337E-7,1,4.99626677034896,40.0298881530762,1.99038754726387,13.6599997058511,8.91190094961552E-5,1.69468296724912E-5,0.25,-5.4893299117942E-7,1.60821661718833E-5,1.54806111246871E-7,54.9997177124023,54.9997177124023,-380.334106445313,-355.359680175781,59.8508589745448,19.9349617647093,2.23507881164551,0,0,0,200,55.0003204345703,1,6,1,2.17575073242187,55.7184753417969,,,,,,,,,,,,,,,,
,3790628647.259,54.9999523162842,-94.6849784851074,6.92569500955136E-7,9.30466485163108E-7,1,4.99626677034896,40.0298881530762,1.99042941925453,13.6599997058511,3.33833298435251E-6,2.55058231000695E-6,0.25,3.1857806773226E-7,6.62647462748814E-7,3.40051571299947E-7,54.9999771118164,54.9999771118164,-107.009536743164,-82.3604202270508,59.9884255939294,19.9404180171235,2.23535418510437,0,0,0,200,54.9999008178711,1,6,1,2.17681884765625,56.2072334289551,,,,,,,,,,,,,,,,
,3790628702.329,54.9999523162842,179.204231262207,-2.24310314901405E-5,7.33973984996804E-7,1,4.99626677034896,40.0298881530762,1.99042129924314,13.6599997058511,-0.000119725209748847,-3.10370938338875E-5,0.25,-7.26378591855123E-7,-2.1864943138122E-5,-1.65091475811474E-6,54.999927520752,54.999927520752,166.696105957031,191.712356567383,59.841479432314,19.9417256985197,2.23512434959412,0,0,0,200,54.9999008178711,1,6,1,2.1771240234375,55.7184753417969,,,,,,,,,,,,,,,,
,3790628757.238,54.999927520752,453.02604675293,-4.10908435408072E-5,6.66051853519431E-7,1,4.99626677034896,40.0298881530762,1.99037308437756,13.6599997058511,-0.000220131063905162,-5.32752241172274E-5,0.25,-6.65125024199587E-7,-4.00834295433449E-5,-2.37410498959455E-6,55.0001373291016,55.0001373291016,440.178680419922,465.873413085937,60.2463630052756,19.938232012683,2.23513412475586,0,0,0,200,54.9996910095215,1,6,1,2.17376708984375,56.2072334289551,,,,,,,,,,,,,,,,
,3790628812.121,55.0000057220459,726.622467041016,-4.43414775999459E-5,6.87413340930481E-7,1,4.99626677034896,40.0298881530762,1.99039654324054,13.6599997058511,-0.000236919412457415,-6.03362295781438E-5,0.25,-1.24731009014956E-6,-4.32341675981685E-5,-3.07821353571018E-6,54.9996910095215,54.9996910095215,714.428039550781,738.81689453125,60.0501742469487,19.9373664905771,2.23526453971863,0,0,0,200,55.0003204345703,1,6,1,2.17681884765625,55.7184753417969,,,,,,,,,,,,,,,,
,3790628867.1815,54.9997825622559,1000.65112304688,-3.03135995564458E-5,1.87295074445968E-6,1,4.99626677034896,40.0298881530762,1.99039047154909,13.6599997058511,-0.000161163679899629,-4.48577273638226E-5,0.25,-1.52418507968505E-6,-2.95299172990901E-5,-2.75944497233774E-6,54.9995079040527,54.9995079040527,988.184814453125,1013.11743164062,59.760190066314,19.940074601013,2.23560690879822,0,0,0,200,55.000057220459,1,6,1,2.17605590820313,55.7184753417969,,,,,,,,,,,,,,,,
,3790628922.0665,54.9997291564941,1273.96875,-2.06260271433686E-6,1.22278941866648E-6,1,4.99626677034896,40.0298881530762,1.99035236252932,13.6700002476573,-9.73306310097261E-6,-8.53612725335214E-6,0.25,-1.12350933903425E-6,-1.96663157424968E-6,-1.18336560890147E-6,54.9996643066406,54.9996643066406,1261.5791015625,1286.3583984375,60.1119228999679,19.9407737576491,2.23573565483093,0,0,0,200,54.9997940063477,1,6,1,2.17498779296875,55.7184753417969,,,,,,,,,,,,,,,,
,3790628977.0145,55.0000171661377,1547.89276123047,3.49702836165681E-5,8.08914304648836E-7,1,4.99626677034896,40.0298881530762,1.99044388994846,13.6700002476573,0.000190741152007063,3.04313635510823E-5,0.25,-2.20517262335148E-6,3.42360542973782E-5,-6.8758314481501E-7,55.0002670288086,55.0002670288086,1535.3544921875,1560.43103027344,60.3229626001602,19.938940007172,2.23551917076111,0,0,0,200,54.9997673034668,1,6,1,2.17620849609375,56.2072334289551,,,,,,,,,,,,,,,,
,3790629031.945,55.000373840332,1821.10339355469,7.98324648763107E-5,7.33740280941961E-7,1,4.99626677034896,40.0298881530762,1.99055551034542,13.6700002476573,0.000431287933579981,8.81409635465264E-5,0.25,-1.56258312417104E-6,7.80152619631091E-5,1.81813555279465E-6,55.000373840332,55.000373840332,1808.60913085938,1833.59765625,59.9172973986794,19.9368692869491,2.23561072349548,0,0,0,200,55.000373840332,1,6,1,2.183837890625,56.2072334289551,,,,,,,,,,,,,,,,
,3790629087.011,54.9999656677246,2095.17395019531,0.000127450967237393,8.30861658596875E-7,1,4.99626677034896,40.0298881530762,1.99035730693859,13.6700002476573,0.000687832621923732,0.000143743979981864,0.25,-1.92753047348226E-6,0.00012453322867493,3.45366935054936E-6,54.9998207092285,54.9998207092285,2082.40795898438,2107.93994140625,60.0501742469487,19.937905781997,2.23568296432495,0,0,0,200,55.0001106262207,1,6,1,2.17208862304687,56.2072334289551,,,,,,,,,,,,,,,,
,3790629141.9505,55.0002689361572,2368.34753417969,0.000179800292822055,8.25600258682099E-7,1,4.99626677034896,40.0298881530762,1.99040404681094,13.6599997058511,0.000969486391696404,0.000207011636685724,0.25,-1.93231740757683E-6,0.000175661671151733,5.63674892612174E-6,55.0001640319824,55.0001640319824,2355.8720703125,2380.82299804687,59.8023980063525,19.9417051105596,2.23589396476746,0,0,0,200,55.0001640319824,1,6,1,2.176513671875,55.7184753417969,,,,,,,,,,,,,,,,
,3790629196.906,54.9998722076416,2642.07629394531,0.000234216419695557,8.06327683243027E-7,1,4.99626677034896,40.0298881530762,1.99044313890638,13.6599997058511,0.00126205827445628,0.000273864166872173,0.25,-1.73442999318888E-6,0.000228806258306464,8.10194951280449E-6,55.000186920166,55.000186920166,2629.80517578125,2654.34741210938,60.1541308400064,19.935197207381,2.23574066162109,0,0,0,200,54.9995574951172,1,6,1,2.17880249023438,56.2072334289551,,,,,,,,,,,,,,,,
,3790629251.8925,55.0001621246338,2916.21875,0.000289979489881099,8.40838648964754E-7,1,4.99626677034896,40.0298881530762,1.99042089245736,13.6700002476573,0.00156331146757637,0.00033597295854076,0.25,-2.71827853489792E-6,0.00028332279396195,9.46675676969123E-6,55.000186920166,55.000186920166,2903.46899414063,2928.96850585937,60.0533007610256,19.9385742002099,2.23585343360901,0,0,0,200,55.0003967285156,1,6,1,2.17788696289062,56.2072334289551,,,,,,,,,,,,,,,,
,3790629306.7995,54.9999523162842,3189.27856445313,0.000347376630430522,7.90472886523751E-7,1,4.99626677034896,40.0298881530762,1.99047593419106,13.6700002476573,0.00187165188945481,0.000408111904700755,0.25,-2.20617284368928E-6,0.00033937961884596,1.23583284952745E-5,54.999927520752,54.999927520752,3177.11889648438,3201.43823242188,60.0517375039871,19.9388262363371,2.23581838607788,0,0,0,200,55.0001640319824,1,6,1,2.18521118164062,56.2072334289551,,,,,,,,,,,,,,,,
,3790629361.7775,54.9994659423828,3463.11413574219,0.000404761534207442,8.80397911255449E-7,1,4.99626677034896,40.0298881530762,1.99029941007513,13.6599997058511,0.00218011061408373,0.000478526753604684,0.25,-2.00103361480863E-6,0.000395444614931304,1.49469203930502E-5,54.9993743896484,54.9993743896484,3451.0615234375,3475.16674804687,60.1728899244679,19.9400636897902,2.2360212802887,0,0,0,200,54.9994812011719,1,6,1,2.17086791992187,56.2072334289551,,,,,,,,,,,,,,,,
,3790629416.766,54.9997425079346,3737.29370117188,0.000463837102248656,9.05096438076509E-7,1,4.99626677034896,40.0298881530762,1.99032000351561,13.6599997058511,0.00249798841242415,0.000550625194359891,0.25,-1.86881657810764E-6,0.000453172200017362,1.75318685734139E-5,54.9993743896484,54.9993743896484,3724.56713867188,3750.02026367188,60.3456298272179,19.9400676534299,2.23605108261108,0,0,0,200,55.0004234313965,1,6,1,2.18551635742187,55.7184753417969,,,,,,,,,,,,,,,,
,3790629471.6675,55.0000324249268,4010.26733398438,0.000522988866521809,1.01996875900641E-6,1,4.99626677034896,40.0298881530762,1.99029328625382,13.6599997058511,0.00281598645908943,0.000624028784101222,0.25,-1.50720872072563E-6,0.00051097245660246,2.03411795403594E-5,54.9999008178711,54.9999008178711,3998.21215820313,4022.32250976562,60.2760648890064,19.940563893391,2.23583054542542,0,0,0,200,55.0002670288086,1,6,1,2.1649169921875,56.2072334289551,,,,,,,,,,,,,,,,
,3790629526.701,55.0002021789551,4284.47021484375,0.000581673137845917,1.00961232279663E-6,1,4.99626677034896,40.0298881530762,1.99028631597981,13.6599997058511,0.00313313600662182,0.000689751618441566,0.25,-2.46721004119986E-6,0.000568379173699059,2.18368287730816E-5,55.0002670288086,55.0002670288086,4272.0576171875,4296.8828125,60.139279898141,19.9376559799095,2.23601269721985,0,0,0,200,55.0001106262207,1,6,1,2.178955078125,55.7184753417969,,,,,,,,,,,,,,,,
,3790629581.7235,54.9994792938232,4558.5732421875,0.000642258781183197,1.06019015558097E-6,1,4.99626677034896,40.0298881530762,1.99040601319704,13.6599997058511,0.00345800825317243,0.00077012038442935,0.25,-1.1398987343296E-6,0.000627555459955626,2.56436053325212E-5,54.9995574951172,54.9995574951172,4546.13037109375,4571.01611328125,60.3604807690833,19.9424949720966,2.23649954795837,0,0,0,200,54.9997940063477,1,6,1,2.1734619140625,55.7184753417969,,,,,,,,,,,,,,,,
,3790629636.615,54.9999141693115,4831.55419921875,0.000701861087072838,1.05366831986208E-6,1,4.99626677034896,40.0298881530762,1.99030338708924,13.6599997058511,0.00377955508137748,0.000839031707889154,0.25,-1.70343094495796E-6,0.000685858952324837,2.75585406236768E-5,54.9999008178711,54.9999008178711,4819.09716796875,4844.01123046875,59.7898919500448,19.9383465455965,2.23636937141418,0,0,0,200,54.999927520752,1,6,1,2.17391967773438,56.2072334289551,,,,,,,,,,,,,,,,
,3790629671.552,55.0009746551514,4996.51342773438,0.000739594111842007,1.50528758226799E-6,1,4.99626677034896,40.0298881530762,1.99026643662001,13.6599997058511,0.00398338860836072,0.000881732786995167,0.25,-2.2328490747727E-6,0.000722780635814456,2.86006509310896E-5,55.0014724731445,55.0014724731445,4993.13720703125,4999.8896484375,60.0837842732756,19.9435348835092,2.23618483543396,0,0,0,200,55.0004768371582,1,4,1,2.17758178710938,55.7184753417969,,,,,,,,,,,,,,,,