File: First Draft/VSM/thinfilm2VSM.csv
Comment,Time Stamp (sec),Temperature (K),Magnetic Field (Oe),Moment (emu),M. Std. Err. (emu),Transport Action,Averaging Time (sec),Frequency (Hz),Peak Amplitude (mm),Center Position (mm),Coil Signal' (mV),Coil Signal" (mV),Range (mV),M. Quad. Signal (emu),M. Raw' (emu),M. Raw" (emu),Min. Temperature (K),Max. Temperature (K),Min. Field (Oe),Max. Field (Oe),Mass (grams),Motor Lag (deg),Pressure (Torr),VSM Status (code),Motor Status (code),Measure Status (code),Measure Count,System Temp. (K),Temp. Status (code),Field Status (code),Chamber Status (code),Motor Current (amps),Motor Heatsink Temp. (C),Map 01,Map 02,Map 03,Map 04,Map 05,Map 06,Map 07,Map 08,Map 09,Map 10,Map 11,Map 12,Map 13,Map 14,Map 15,Map 16
sample offset = 34 mm,3792809008.889,55.1065330505371,-0.0996374413371086,-5.6288294678797E-7,3.54941268497806E-7,1,4.99626677034896,40.0298881530762,2.00056410963929,15.7200004905462,-3.01691798960113E-6,-7.95232425144352E-7,0.25,-2.05577554363023E-8,-5.4866155055428E-7,-4.36767381715049E-8,55.1065330505371,55.1065330505371,-0.0996374413371086,-0.0996374413371086,57.3957637956407,20.3506435351293,9.89999989542412E-6,0,0,0,200,53.9534187316895,1,4,14,2.2332763671875,37.1456527709961,,,,,,,,,,,,,,,,
,3792809061.4175,55.0682220458984,204.765991210938,1.90105510656171E-6,6.34693754924213E-7,1,4.99626677034896,40.0298881530762,2.00030707921072,15.7200004905462,1.06611286398549E-5,5.79819283104931E-7,0.25,-3.20274227604385E-7,1.86930446776799E-6,-2.32908452531068E-7,55.0699691772461,55.0699691772461,191.669982910156,217.861999511719,57.9640077291215,20.3545652619132,9.89999989542412E-6,0,0,0,200,54.0157890319824,1,6,14,2.220458984375,42.0332374572754,,,,,,,,,,,,,,,,
,3792809111.312,55.0382690429687,453.213714599609,4.66686142171005E-6,7.69624368048992E-7,1,4.99626677034896,40.0298881530762,2.00026307402931,15.7200004905462,2.46183105590798E-5,8.32653277478491E-6,0.25,4.91383485405959E-7,4.53527324022081E-6,6.75499191945006E-7,55.0399627685547,55.0399627685547,440.433715820313,465.993713378906,58.0320094102946,20.3583435776368,9.89999989542412E-6,0,0,0,200,54.0728073120117,1,6,14,2.24456787109375,43.9882698059082,,,,,,,,,,,,,,,,
,3792809161.249,55.0151271820068,701.88916015625,4.3932424401282E-6,8.14970932461701E-7,1,4.99626677034896,40.0298881530762,1.99984883896367,15.7200004905462,2.26368828116602E-5,1.02088375351559E-5,0.25,9.01681308250839E-7,4.25097228243786E-6,1.06455770079091E-6,55.0161361694336,55.0161361694336,689.392639160156,714.385681152344,57.9061672186984,20.3588658593994,9.89999989542412E-6,0,0,0,200,54.1281929016113,1,6,14,2.23983764648438,45.9433059692383,,,,,,,,,,,,,,,,
,3792809211.186,54.998327255249,950.636657714844,2.96003482768181E-6,7.72560915920362E-7,1,4.99626677034896,40.0298881530762,1.99968633951842,15.7200004905462,1.55288687587754E-5,5.64322046523019E-6,0.25,3.78957894187614E-7,2.87382325932658E-6,4.94120972187865E-7,54.9991149902344,54.9991149902344,938.096008300781,963.177307128906,57.7943943404484,20.3605152846725,9.89999989542412E-6,0,0,0,200,54.174373626709,1,6,14,2.23495483398438,46.9208221435547,,,,,,,,,,,,,,,,
,3792809261.27,54.9837207794189,1200.06268310547,-2.73356201301879E-7,2.6095715874124E-7,1,4.99626677034896,40.0298881530762,1.99947591785915,15.7200004905462,-2.57055412725674E-6,4.53258137899557E-6,0.25,9.00642346502845E-7,-3.04641063604801E-7,8.67805200787548E-7,54.9841918945313,54.9841918945313,1187.24548339844,1212.8798828125,58.1852086000638,20.3600257258764,9.89999989542412E-6,0,0,0,200,54.2160835266113,1,6,14,2.2216796875,47.4095802307129,,,,,,,,,,,,,,,,
,3792809311.153,54.9724750518799,1448.91467285156,-4.65348415050986E-6,6.77553273684645E-7,1,4.99626677034896,40.0298881530762,1.99936332586852,15.7200004905462,-2.67913921320416E-5,1.71564309384338E-6,0.25,1.36416218584016E-6,-4.60039448086862E-6,1.13672163747238E-6,54.9731826782227,54.9731826782227,1436.99438476562,1460.8349609375,58.2055309415639,20.3596380414926,9.89999989542412E-6,0,0,0,200,54.2561569213867,1,6,14,2.23403930664062,48.3870964050293,,,,,,,,,,,,,,,,
,3792809361.1795,54.9635639190674,1698.17327880859,-9.66301207951862E-6,7.12444750782675E-7,1,4.99626677034896,40.0298881530762,1.99918019844374,15.7200004905462,-5.37007915625378E-5,-5.01433674914362E-6,0.25,1.24454182811662E-6,-9.48651841488203E-6,8.10067207254947E-7,54.9636154174805,54.9636154174805,1686.2646484375,1710.08190917969,58.0851601496023,20.3506389037265,9.89999989542412E-6,0,0,0,200,54.298267364502,1,6,14,2.22457885742187,49.364616394043,,,,,,,,,,,,,,,,
,3792809411.0855,54.9571552276611,1946.60473632813,-1.57881048585346E-5,7.57531790668922E-7,1,4.99626677034896,40.0298881530762,1.99916374968943,15.7200004905462,-8.72843358733969E-5,-1.0232286490589E-5,0.25,1.65558876758836E-6,-1.5484530149453E-5,9.54955040411775E-7,54.9572486877441,54.9572486877441,1933.89916992187,1959.31030273438,58.68701410941,20.3514113742782,9.89999989542412E-6,0,0,0,200,54.3371810913086,1,6,14,2.22122192382813,49.8533744812012,,,,,,,,,,,,,,,,
,3792809461.061,54.9524765014648,2195.08032226562,-2.21369716365723E-5,7.61895075421484E-7,1,4.99626677034896,40.0298881530762,1.99906817126826,15.7200004905462,-0.000121567136804421,-1.79783830309681E-5,0.25,1.64859295491667E-6,-2.16841079941519E-5,6.82537058892388E-7,54.9526596069336,54.9526596069336,2182.62084960938,2207.53979492187,58.537723062237,20.3497144313763,9.89999989542412E-6,0,0,0,200,54.3731307983398,1,6,14,2.22320556640625,49.8533744812012,,,,,,,,,,,,,,,,
,3792809511.0405,54.9495964050293,2444.60400390625,-2.90463545738284E-5,7.5653016560104E-7,1,4.99626677034896,40.0298881530762,1.99894812847936,15.7200004905462,-0.000159286740658361,-2.45781314090177E-5,0.25,1.97952834669996E-6,-2.84458508069537E-5,7.16886747931941E-7,54.9496231079102,54.9496231079102,2432.13305664062,2457.07495117187,58.1805188289485,20.3465390768074,9.89999989542412E-6,0,0,0,200,54.4073638916016,1,6,14,2.2174072265625,50.8308906555176,,,,,,,,,,,,,,,,
,3792809560.9925,54.9481410980225,2693.06555175781,-3.60033802459766E-5,8.50821139775046E-7,1,4.99626677034896,40.0298881530762,1.99897443161856,15.7200004905462,-0.000196912305022888,-3.28626792527751E-5,0.25,2.00933888953937E-6,-3.52422886621956E-5,4.55510043256697E-7,54.9483108520508,54.9483108520508,2681.05004882813,2705.0810546875,58.3939034146985,20.3416532800313,9.89999989542412E-6,0,0,0,200,54.4400367736816,1,6,14,2.2381591796875,50.8308906555176,,,,,,,,,,,,,,,,
,3792809610.983,54.9476165771484,2942.00134277344,-4.32857381947168E-5,8.2249255267913E-7,1,4.99626677034896,40.0298881530762,1.99885263624931,15.7200004905462,-0.000236602900355151,-4.01203886100445E-5,0.25,2.30170105440033E-6,-4.23682482872247E-5,4.37237396805054E-7,54.9475250244141,54.9475250244141,2929.81860351562,2954.18408203125,58.3712361876408,20.3360398721142,9.89999989542412E-6,0,0,0,200,54.4697036743164,1,6,14,2.222900390625,51.3196487426758,,,,,,,,,,,,,,,,
,3792809660.8235,54.9474868774414,3190.26330566406,-5.08436151416287E-5,8.2803954230077E-7,1,4.99626677034896,40.0298881530762,1.99879967717771,15.7200004905462,-0.000278264781937443,-4.560584075055E-5,0.25,2.98400856261732E-6,-4.97804386373563E-5,7.88629673014954E-7,54.9471855163574,54.9471855163574,3177.79223632812,3202.734375,58.5072395499869,20.3342938622705,9.89999989542412E-6,0,0,0,200,54.4971923828125,1,6,14,2.2088623046875,51.3196487426758,,,,,,,,,,,,,,,,
,3792809710.84,54.9484558105469,3439.2802734375,-5.84317788691225E-5,8.28718293502283E-7,1,4.99626677034896,40.0298881530762,1.99878856462898,15.7200004905462,-0.000318500613481253,-5.82465563727289E-5,0.25,2.34842319553424E-6,-5.71681023131342E-5,-1.47970726213407E-7,54.9484176635742,54.9484176635742,3426.76049804687,3451.80004882812,58.4501806680831,20.3315165634262,9.89999989542412E-6,0,0,0,200,54.5227012634277,1,6,14,2.23663330078125,51.808406829834,,,,,,,,,,,,,,,,
,3792809760.8065,54.9500274658203,3687.52587890625,-6.61618625245097E-5,8.69933123313187E-7,1,4.99626677034896,40.0298881530762,1.99878814424466,15.7200004905462,-0.000360606424242073,-6.61816460865178E-5,0.25,2.61568515404126E-6,-6.47330991198713E-5,-2.08348066586966E-7,54.9498558044434,54.9498558044434,3674.97119140625,3700.08056640625,58.466594866987,20.3310709696693,9.89999989542412E-6,0,0,0,200,54.5435829162598,1,6,14,2.23403930664062,51.808406829834,,,,,,,,,,,,,,,,
,3792809810.7835,54.9514694213867,3936.58923339844,-7.42281533771388E-5,8.67811343798441E-7,1,4.99626677034896,40.0298881530762,1.99873436716004,15.7200004905462,-0.000404061614599937,-7.65792644304907E-5,0.25,2.50209003359447E-6,-7.26115686280374E-5,-6.54390357082939E-7,54.9513244628906,54.9513244628906,3923.767578125,3949.41088867188,58.5213088633331,20.326762516396,9.89999989542412E-6,0,0,0,200,54.5659828186035,1,6,14,2.20977783203125,52.7859268188477,,,,,,,,,,,,,,,,
,3792809860.669,54.9529895782471,4184.658203125,-8.25318436716801E-5,1.74797632441362E-6,1,4.99626677034896,40.0298881530762,1.99881648875839,15.7200004905462,-0.000449718122736167,-8.33284938839317E-5,0.25,3.11782917178927E-6,-8.07533934334938E-5,-3.97500845186887E-7,54.9530029296875,54.9530029296875,4172.13623046875,4197.18017578125,58.4673764955062,20.3260344352628,9.89999989542412E-6,0,0,0,200,54.5868377685547,1,6,14,2.21969604492187,52.2971649169922,,,,,,,,,,,,,,,,
,3792809910.7155,54.9547958374023,4434.021484375,-9.114570140402E-5,8.52374196291895E-7,1,4.99626677034896,40.0298881530762,1.99863493536898,15.7200004905462,-0.000496469486422782,-9.27908354938665E-5,0.25,3.29873676103648E-6,-8.91811983946515E-5,-5.77842921057661E-7,54.9548606872559,54.9548606872559,4421.87109375,4446.171875,58.4134441276792,20.3207393669483,9.89999989542412E-6,0,0,0,200,54.6064300537109,1,6,14,2.22152709960938,52.7859268188477,,,,,,,,,,,,,,,,
,3792809960.7225,54.9563446044922,4682.845703125,-9.86907555112041E-5,9.28036442939082E-7,1,4.99626677034896,40.0298881530762,1.99868170974903,15.7200004905462,-0.000537474790285077,-0.000101094355364931,0.25,3.455610104267E-6,-9.65648432215728E-5,-7.36695812835694E-7,54.9562530517578,54.9562530517578,4670.32373046875,4695.36767578125,58.3032345064677,20.3199713247892,9.89999989542412E-6,0,0,0,200,54.6248664855957,1,6,14,2.23312377929687,53.2746849060059,,,,,,,,,,,,,,,,
,3792810010.666,54.9582424163818,4931.33544921875,-0.000107112645837485,1.01512328019314E-6,1,4.99626677034896,40.0298881530762,1.99864434935767,15.7200004905462,-0.000583169085267019,-0.000110606115259025,0.25,3.58479311846496E-6,-0.00010480508362097,-9.58705502529902E-7,54.9579277038574,54.9579277038574,4918.84619140625,4943.82470703125,58.4955151221985,20.3156123169632,9.89999989542412E-6,0,0,0,200,54.6416435241699,1,6,14,2.2222900390625,53.2746849060059,,,,,,,,,,,,,,,,
,3792810065.6505,54.9612827301025,4869.99145507812,-0.000105226149825915,9.86647633359741E-7,1,4.99626677034896,40.0298881530762,1.99851021870322,15.7200004905462,-0.000572964859014418,-0.00010815979616319,0.25,3.61282283113325E-6,-0.00010296193671608,-8.5319519060747E-7,54.9609413146973,54.9609413146973,4857.5390625,4882.44384765625,58.5736779741216,20.3134645369648,9.89999989542412E-6,0,0,0,200,54.6569938659668,1,6,14,2.20901489257813,53.2746849060059,,,,,,,,,,,,,,,,
,3792810115.5695,54.9625797271729,4621.45532226562,-9.70059248315648E-5,9.45336887341829E-7,1,4.99626677034896,40.0298881530762,1.99857125955865,15.7200004905462,-0.000528073644626077,-0.000100226839106147,0.25,3.23689799395475E-6,-9.49091046502424E-5,-8.80385575602405E-7,54.9627227783203,54.9627227783203,4608.97021484375,4633.9404296875,58.6877957379293,20.3121079598275,9.89999989542412E-6,0,0,0,200,54.6733360290527,1,6,14,2.22305297851562,53.2746849060059,,,,,,,,,,,,,,,,
,3792810165.52,54.9649658203125,4372.74462890625,-8.84989633272028E-5,9.15713495564164E-7,1,4.99626677034896,40.0298881530762,1.99853606080789,15.7200004905462,-0.000481677091790941,-9.16617347582857E-5,0.25,2.91239420969827E-6,-8.65794152287049E-5,-8.44900930608575E-7,54.964900970459,54.964900970459,4360.22021484375,4385.26904296875,58.4181338987946,20.3086332370287,9.89999989542412E-6,0,0,0,200,54.685619354248,1,6,14,2.21878051757813,53.2746849060059,,,,,,,,,,,,,,,,
,3792810215.428,54.9669952392578,4124.27392578125,-8.12119143923772E-5,8.54233494884941E-7,1,4.99626677034896,40.0298881530762,1.99849218557369,15.7200004905462,-0.000442434854516642,-8.20896450826968E-5,0.25,3.04807763247449E-6,-7.94615826459081E-5,-4.10358577542267E-7,54.9670219421387,54.9670219421387,4111.76318359375,4136.78466796875,58.3829606154293,20.3091534208792,9.89999989542412E-6,0,0,0,200,54.6990242004395,1,6,14,2.22183227539062,53.7634429931641,,,,,,,,,,,,,,,,
,3792810265.435,54.9687919616699,3875.66821289063,-7.22726343075014E-5,7.79683863361631E-7,1,4.99626677034896,40.0298881530762,1.99846928832498,15.7200004905462,-0.000393090013427813,-7.58009763356697E-5,0.25,2.20480669334035E-6,-7.06897868476472E-5,-8.62822648287093E-7,54.9688034057617,54.9688034057617,3863.47387695313,3887.86254882812,58.6307368560254,20.3066212878455,9.89999989542412E-6,0,0,0,200,54.7100830078125,1,6,14,2.21969604492187,53.2746849060059,,,,,,,,,,,,,,,,
,3792810315.4155,54.9703121185303,3626.82995605469,-6.43941958301899E-5,8.59539090019458E-7,1,4.99626677034896,40.0298881530762,1.99854015831052,15.7200004905462,-0.000349999330505017,-6.85718118283075E-5,0.25,1.77430723516942E-6,-6.29724010073758E-5,-9.55931245051569E-7,54.9701690673828,54.9701690673828,3614.74243164063,3638.91748046875,58.6424612838139,20.3028941102552,9.89999989542412E-6,0,0,0,200,54.7211456298828,1,6,14,2.22091674804687,53.7634429931641,,,,,,,,,,,,,,,,
,3792810365.418,54.972146987915,3378.0361328125,-5.70179248091743E-5,9.12245478795628E-7,1,4.99626677034896,40.0298881530762,1.99850490473045,15.7200004905462,-0.000310632817122656,-5.73856449326769E-5,0.25,2.18831783382553E-6,-5.57816976356894E-5,-2.44773280575248E-7,54.9724998474121,54.9724998474121,3364.91455078125,3391.15771484375,58.3173038198139,20.3021420268399,9.89999989542412E-6,0,0,0,200,54.7315063476562,1,6,14,2.22000122070313,53.7634429931641,,,,,,,,,,,,,,,,
,3792810415.362,54.9734306335449,3129.54431152344,-4.9375244579819E-5,8.71556683989599E-7,1,4.99626677034896,40.0298881530762,1.9983741595059,15.7200004905462,-0.000268277945264646,-5.27402185875811E-5,0.25,1.33093880640504E-6,-4.82784814579963E-5,-7.63943106357785E-7,54.9731826782227,54.9731826782227,3117.04321289063,3142.04541015625,58.47362952366,20.2998700133798,9.89999989542412E-6,0,0,0,200,54.7419204711914,1,6,14,2.20794677734375,53.7634429931641,,,,,,,,,,,,,,,,
,3792810465.391,54.9747943878174,2880.55969238281,-4.16137717402978E-5,7.88254505443856E-7,1,4.99626677034896,40.0298881530762,1.99848986934553,15.7200004905462,-0.000226404444844003,-4.31263782139225E-5,0.25,1.36772048917524E-6,-4.06974780622939E-5,-4.04488273802353E-7,54.9746513366699,54.9746513366699,2868.79516601562,2892.32421875,58.4071910995254,20.3010260816236,9.89999989542412E-6,0,0,0,200,54.7515258789063,1,6,14,2.220458984375,54.2522010803223,,,,,,,,,,,,,,,,
,3792810515.2925,54.9767360687256,2631.54516601562,-3.4271627168204E-5,7.6899807923279E-7,1,4.99626677034896,40.0298881530762,1.9984736548862,15.7200004905462,-0.00018648249694074,-3.53597079601673E-5,0.25,1.15594522599764E-6,-3.35164675951344E-5,-3.04980832337608E-7,54.9765396118164,54.9765396118164,2619.06494140625,2644.025390625,58.7128078505447,20.2956117972275,9.89999989542412E-6,0,0,0,200,54.7589683532715,1,6,14,2.23114013671875,53.7634429931641,,,,,,,,,,,,,,,,
,3792810565.258,54.9778614044189,2382.86962890625,-2.65538477856779E-5,7.38359058572095E-7,1,4.99626677034896,40.0298881530762,1.99843025600151,15.7200004905462,-0.000145012704239639,-2.50123704609386E-5,0.25,1.33741968624239E-6,-2.59858615134813E-5,1.94556774088551E-7,54.9777183532715,54.9777183532715,2370.35229492187,2395.38696289062,58.54475771891,20.299331570838,9.89999989542412E-6,0,0,0,200,54.7652854919434,1,6,14,2.22991943359375,54.2522010803223,,,,,,,,,,,,,,,,
,3792810615.18,54.9790267944336,2134.28479003906,-2.03057062913838E-5,7.34780980715991E-7,1,4.99626677034896,40.0298881530762,1.99848396757758,15.7200004905462,-0.000111097886834346,-1.81946227461453E-5,0.25,1.19572437678306E-6,-1.98775878078745E-5,3.17277610415287E-7,54.9790267944336,54.9790267944336,2121.79760742187,2146.77197265625,58.3993748143331,20.2930610519808,9.89999989542412E-6,0,0,0,200,54.7729644775391,1,6,14,2.20626831054687,54.2522010803223,,,,,,,,,,,,,,,,
,3792810665.2635,54.9802742004395,1884.57525634766,-1.3121197902376E-5,7.14311066459398E-7,1,4.99626677034896,40.0298881530762,1.99832820948821,15.7200004905462,-7.16193139325176E-5,-1.24726660783719E-5,0.25,6.40110770443605E-7,-1.28383556615028E-5,7.53268530705584E-8,54.9802093505859,54.9802093505859,1872.099609375,1897.05090332031,58.6745080531024,20.2956380469287,9.89999989542412E-6,0,0,0,200,54.7815818786621,1,6,14,2.22091674804687,54.2522010803223,,,,,,,,,,,,,,,,
,3792810715.049,54.9808883666992,1636.85485839844,-7.07504539220916E-6,6.94569663147542E-7,1,4.99626677034896,40.0298881530762,1.99837019893574,15.7200004905462,-3.97736660219439E-5,-1.57942207280154E-6,0.25,1.2984073038316E-6,-6.96214056142725E-6,9.71185655967358E-7,54.9806518554687,54.9806518554687,1624.6650390625,1649.04467773438,58.7683034754101,20.2942817935799,9.89999989542412E-6,0,0,0,200,54.7881126403809,1,6,14,2.21893310546875,54.2522010803223,,,,,,,,,,,,,,,,
,3792810765.1695,54.9827651977539,1387.72174072266,-1.52013954155235E-6,6.15937277733301E-7,1,4.99626677034896,40.0298881530762,1.99834349676359,15.7200004905462,-8.79688651960398E-6,7.79556627179935E-7,0.25,4.86262831216961E-7,-1.50450552087491E-6,4.11006207333117E-7,54.9828300476074,54.9828300476074,1375.208984375,1400.23449707031,58.4267318125062,20.2914327960861,9.89999989542412E-6,0,0,0,200,54.7934188842773,1,6,14,2.21954345703125,54.2522010803223,,,,,,,,,,,,,,,,
,3792810815.0075,54.9835376739502,1139.29034423828,3.10279618676675E-6,7.30867343235672E-7,1,4.99626677034896,40.0298881530762,1.99840127030669,15.7200004905462,1.68134481193277E-5,3.48593603022442E-6,0.25,-5.21101428942321E-8,3.03131361532839E-6,7.92673541452154E-8,54.9836959838867,54.9836959838867,1127.02612304688,1151.55456542969,58.6010349722947,20.2936754169326,9.89999989542412E-6,0,0,0,200,54.7988548278809,1,6,14,2.22000122070313,54.2522010803223,,,,,,,,,,,,,,,,
,3792810865.0435,54.983865737915,889.731811523437,7.66575972803577E-6,7.45660994743514E-7,1,4.99626677034896,40.0298881530762,1.99844745627482,15.7200004905462,4.1454748288806E-5,8.98363796424428E-6,0.25,-6.00669286227874E-8,7.48592764421801E-6,2.63008595418365E-7,54.9836158752441,54.9836158752441,877.518798828125,901.94482421875,58.4572153247562,20.287953174191,9.89999989542412E-6,0,0,0,200,54.8058319091797,1,6,14,2.2052001953125,54.2522010803223,,,,,,,,,,,,,,,,
,3792810914.95,54.9851379394531,641.300384521484,9.70827465566184E-6,6.47366060189771E-7,1,4.99626677034896,40.0298881530762,1.99841559416314,15.7200004905462,5.24010669374998E-5,1.18041469841391E-5,0.25,2.96358828244965E-9,9.47680970402018E-6,4.10381888074412E-7,54.9853210449219,54.9853210449219,628.532043457031,654.068725585938,58.5611719178139,20.2917507640448,9.89999989542412E-6,0,0,0,200,54.8114738464355,1,6,14,2.22244262695313,54.2522010803223,,,,,,,,,,,,,,,,
,3792810964.917,54.9858722686768,392.926986694336,9.60137063287647E-6,6.94729464136433E-7,1,4.99626677034896,40.0298881530762,1.99838345460748,15.7200004905462,5.24344139855047E-5,8.94767949991838E-6,0.25,-5.02227269791316E-7,9.39329120437114E-6,-8.71077157967023E-8,54.9859771728516,54.9859771728516,380.707000732422,405.14697265625,58.730785306487,20.2918801248403,9.89999989542412E-6,0,0,0,200,54.815788269043,1,6,14,2.21633911132813,54.7409591674805,,,,,,,,,,,,,,,,
,3792811014.9825,54.9864597320557,143.749656677246,8.61266939097343E-6,6.67353198189714E-7,1,4.99626677034896,40.0298881530762,1.99829138275212,15.7200004905462,4.7385068653307E-5,6.45312206268696E-6,0.25,-7.41991976803774E-7,8.43796973531924E-6,-3.62534186895592E-7,54.9862632751465,54.9862632751465,131.287994384766,156.211318969727,58.7167159931408,20.2897568754935,9.89999989542412E-6,0,0,0,200,54.8207015991211,1,6,14,2.2314453125,54.7409591674805,,,,,,,,,,,,,,,,
,3792811064.89,54.9874572753906,-104.598159790039,2.05665177509879E-6,7.89698120634758E-7,1,4.99626677034896,40.0298881530762,1.99841011928737,15.7200004905462,1.06156963100042E-5,4.65328680031146E-6,0.25,3.99424470870521E-7,1.99071062949455E-6,4.7625540285584E-7,54.987678527832,54.987678527832,-117.136489868164,-92.0598297119141,58.9707452618909,20.2911783987494,9.89999989542412E-6,0,0,0,200,54.8250427246094,1,6,14,2.21847534179687,54.7409591674805,,,,,,,,,,,,,,,,
,3792811114.803,54.9883899688721,-352.934356689453,-3.67232173723144E-6,7.20267295705595E-7,1,4.99626677034896,40.0298881530762,1.9984217578935,15.7200004905462,-1.94165389072248E-5,-6.26216300716475E-6,0.25,-3.34018837143556E-7,-3.57063765921177E-6,-4.80238110150542E-7,54.9884948730469,54.9884948730469,-365.063720703125,-340.804992675781,58.4118808706408,20.2867880492816,9.89999989542412E-6,0,0,0,200,54.8287544250488,1,6,14,2.2064208984375,54.7409591674805,,,,,,,,,,,,,,,,
,3792811164.863,54.9893054962158,-602.416137695313,-5.17087595716715E-6,8.07417597938067E-7,1,4.99626677034896,40.0298881530762,1.99833401351653,15.7200004905462,-2.70676367943649E-5,-1.00274271461544E-5,0.25,-6.94553156406593E-7,-5.01850456611548E-6,-8.95041617473345E-7,54.9894638061523,54.9894638061523,-614.919616699219,-589.912658691406,58.6174491711985,20.2892484995752,9.89999989542412E-6,0,0,0,200,54.8314743041992,1,6,14,2.21939086914062,54.7409591674805,,,,,,,,,,,,,,,,
,3792811214.8755,54.9898433685303,-851.533050537109,-4.24580308756992E-6,7.99896032176352E-7,1,4.99626677034896,40.0298881530762,1.99839985289684,15.7200004905462,-2.19894258102577E-5,-9.29023038581168E-6,0.25,-7.66008690614097E-7,-4.11267377242047E-6,-9.25934305533563E-7,54.9900131225586,54.9900131225586,-864.296752929688,-838.769348144531,58.5322516626023,20.2869127077661,9.89999989542412E-6,0,0,0,200,54.8366775512695,1,6,14,2.23052978515625,54.7409591674805,,,,,,,,,,,,,,,,
,3792811264.754,54.9899215698242,-1099.92034912109,-1.48241816738861E-6,9.35693268247266E-7,1,4.99626677034896,40.0298881530762,1.99835341311218,15.7200004905462,-7.35129927894044E-6,-4.69543358790817E-6,0.25,-5.36392102170521E-7,-1.42472787679369E-6,-5.85833709890271E-7,54.989803314209,54.989803314209,-1112.10314941406,-1087.73754882812,58.2633714519869,20.2887422383641,9.89999989542412E-6,0,0,0,200,54.8401031494141,1,6,14,2.20687866210938,55.7184753417969,,,,,,,,,,,,,,,,
,3792811314.746,54.9905643463135,-1348.64691162109,2.20885340260816E-6,5.87768556024064E-7,1,4.99626677034896,40.0298881530762,1.99836872906763,15.7200004905462,1.33861152572192E-5,-3.8163845085247E-6,0.25,-1.2036582708993E-6,2.20698494134798E-6,-1.08253530183698E-6,54.9907493591309,54.9907493591309,-1360.83435058594,-1336.45947265625,58.598690086737,20.2888951010821,9.89999989542412E-6,0,0,0,200,54.8427696228027,1,6,14,2.21923828125,54.7409591674805,,,,,,,,,,,,,,,,
,3792811364.6875,54.9913387298584,-1597.00866699219,7.26491067789874E-6,6.31537256192861E-7,1,4.99626677034896,40.0298881530762,1.99844301231582,15.7200004905462,4.069753720986E-5,2.26775627171884E-6,0.25,-1.21360025070692E-6,7.14401469244094E-6,-8.80456926694111E-7,54.9914054870605,54.9914054870605,-1609.7607421875,-1584.25659179687,58.5963452011793,20.2914819749674,9.89999989542412E-6,0,0,0,200,54.8446769714355,1,6,14,2.22122192382813,54.7409591674805,,,,,,,,,,,,,,,,
,3792811414.6555,54.9915351867676,-1845.64923095703,1.28505316805798E-5,7.20346867994289E-7,1,4.99626677034896,40.0298881530762,1.99834211668011,15.7200004905462,7.09989477150826E-5,8.4088553674141E-6,0.25,-1.33191552325766E-6,1.26031693809126E-5,-7.62197599666903E-7,54.9917449951172,54.9917449951172,-1858.10620117187,-1833.19226074219,58.7479811339101,20.2898276428756,9.89999989542412E-6,0,0,0,200,54.8488616943359,1,6,14,2.21923828125,54.2522010803223,,,,,,,,,,,,,,,,
,3792811464.5635,54.9925441741943,-2094.23400878906,1.95573093059226E-5,6.89801232311498E-7,1,4.99626677034896,40.0298881530762,1.99839202612803,15.7200004905462,0.00010771969857898,1.43207745792508E-5,0.25,-1.74468943353417E-6,1.91700279963729E-5,-8.84758616416649E-7,54.9926109313965,54.9926109313965,-2107.10693359375,-2081.36108398438,58.6049431148908,20.2895190660227,9.89999989542412E-6,0,0,0,200,54.8523139953613,1,6,14,2.2186279296875,54.7409591674805,,,,,,,,,,,,,,,,
,3792811514.5675,54.9928703308105,-2342.93969726562,2.63981013546777E-5,8.42319499315556E-7,1,4.99626677034896,40.0298881530762,1.99842482452788,15.7200004905462,0.000145154712368521,2.0457737143506E-5,0.25,-2.14575475912692E-6,2.58679657522348E-5,-9.90580244779336E-7,54.9928703308105,54.9928703308105,-2355.1689453125,-2330.71044921875,58.3563852457754,20.2868484663752,9.89999989542412E-6,0,0,0,200,54.8534393310547,1,6,14,2.22076416015625,54.7409591674805,,,,,,,,,,,,,,,,
,3792811564.506,54.9929370880127,-2591.71276855469,3.33453764295858E-5,7.65084115595093E-7,1,4.99626677034896,40.0298881530762,1.99834279643218,15.7200004905462,0.000182931833893626,2.77374161326998E-5,0.25,-2.35871583794927E-6,3.26627587042058E-5,-9.08567470886315E-7,54.9925575256348,54.9925575256348,-2604.16967773438,-2579.255859375,58.1836453430254,20.2863021594446,9.89999989542412E-6,0,0,0,200,54.856315612793,1,6,14,2.21832275390625,54.7409591674805,,,,,,,,,,,,,,,,
,3792811614.522,54.9933166503906,-2840.56018066406,4.07360983679148E-5,7.73698200964836E-7,1,4.99626677034896,40.0298881530762,1.99836467411727,15.7200004905462,0.000222711006909063,3.73606379799349E-5,0.25,-2.23742969138408E-6,3.98774554200456E-5,-4.81900202927859E-7,54.9935531616211,54.9935531616211,-2852.74291992187,-2828.37744140625,58.7604871902178,20.2843121225108,9.89999989542412E-6,0,0,0,200,54.8594551086426,1,6,14,2.22091674804687,54.7409591674805,,,,,,,,,,,,,,,,
,3792811664.433,54.9934234619141,-3089.22399902344,4.82664416204192E-5,8.00502266645021E-7,1,4.99626677034896,40.0298881530762,1.99838768449013,15.7200004905462,0.00026422226856529,4.28273639308648E-5,0.25,-2.91700970089309E-6,4.72628293487979E-5,-8.31883569535534E-7,54.9936866760254,54.9936866760254,-3102.08764648438,-3076.3603515625,58.4525255536408,20.2865406379607,9.89999989542412E-6,0,0,0,200,54.8632507324219,1,6,14,2.21725463867187,54.7409591674805,,,,,,,,,,,,,,,,
,3792811714.3895,54.9933834075928,-3337.62048339844,5.6047332548377E-5,7.73175227402092E-7,1,4.99626677034896,40.0298881530762,1.9984017539711,15.7200004905462,0.000306061006996416,5.31827009744093E-5,0.25,-2.7475308349739E-6,5.48582966376638E-5,-3.42491595536681E-7,54.9934501647949,54.9934501647949,-3349.47583007812,-3325.76513671875,58.7276587924101,20.2859560903895,9.89999989542412E-6,0,0,0,200,54.864818572998,1,6,14,2.220458984375,54.7409591674805,,,,,,,,,,,,,,,,
,3792811764.364,54.9950618743897,-3586.18664550781,6.40314992816326E-5,8.58367884218962E-7,1,4.99626677034896,40.0298881530762,1.99828297282891,15.7200004905462,0.000349796273310752,6.01565285634434E-5,0.25,-3.24884058902156E-6,6.26814179665068E-5,-5.00229782160516E-7,54.9952583312988,54.9952583312988,-3598.25805664063,-3574.115234375,58.801913501737,20.2884047711531,9.89999989542412E-6,0,0,0,200,54.8638496398926,1,6,14,2.22000122070313,54.7409591674805,,,,,,,,,,,,,,,,
,3792811814.366,54.9943027496338,-3835.31750488281,7.21844684032216E-5,8.68260560811726E-7,1,4.99626677034896,40.0298881530762,1.99838097800169,15.7200004905462,0.000393937741656124,6.97731382133158E-5,0.25,-3.29979796633667E-6,7.06513722784954E-5,-2.11324914819152E-7,54.9943161010742,54.9943161010742,-3847.82104492188,-3822.81396484375,58.4110992421216,20.2870653792788,9.89999989542412E-6,0,0,0,200,54.8672523498535,1,6,14,2.2222900390625,54.7409591674805,,,,,,,,,,,,,,,,
,3792811864.3615,54.99440574646,-4083.92321777344,8.06471771356657E-5,7.99576019392504E-7,1,4.99626677034896,40.0298881530762,1.99832303229438,15.7200004905462,0.000439114174964337,8.24997302346233E-5,0.25,-2.84345773242267E-6,7.89038206574928E-5,5.85671179861917E-7,54.9944458007812,54.9944458007812,-4095.79931640625,-4072.04711914063,58.8964905525639,20.2879236800483,9.89999989542412E-6,0,0,0,200,54.8702621459961,1,6,14,2.22198486328125,56.2072334289551,,,,,,,,,,,,,,,,
,3792811914.277,54.994421005249,-4332.83569335937,8.76855478348263E-5,9.93200100465212E-7,1,4.99626677034896,40.0298881530762,1.99835100508165,15.7200004905462,0.000478109852993743,8.68648938220669E-5,0.25,-3.61535568842859E-6,8.5816984907372E-5,1.23002018579273E-7,54.9943161010742,54.9943161010742,-4344.93017578125,-4320.7412109375,58.4572153247562,20.2836954008961,9.89999989542412E-6,0,0,0,200,54.8716201782227,1,6,14,2.220458984375,54.7409591674805,,,,,,,,,,,,,,,,
,3792811964.198,54.9947338104248,-4581.10229492188,9.65000617878418E-5,9.08467801250063E-7,1,4.99626677034896,40.0298881530762,1.99840966481474,15.7200004905462,0.000526143815570632,9.59337624432777E-5,0.25,-3.9155369109428E-6,9.44467166968033E-5,1.94771302920242E-7,54.9948387145996,54.9948387145996,-4593.2060546875,-4568.99853515625,58.7151527361024,20.289674629603,9.89999989542412E-6,0,0,0,200,54.8725891113281,1,6,14,2.22259521484375,54.2522010803223,,,,,,,,,,,,,,,,
,3792812014.162,54.994930267334,-4829.41333007812,0.000104707546302315,8.95003478435101E-7,1,4.99626677034896,40.0298881530762,1.99829306876024,15.7200004905462,0.000570794398744331,0.00010454025811592,0.25,-4.16315902026437E-6,0.000102482212467621,2.92165250979921E-7,54.9948654174805,54.9948654174805,-4842.3095703125,-4816.51708984375,58.5166190922177,20.2855009426294,9.89999989542412E-6,0,0,0,200,54.8763847351074,1,6,14,2.22015380859375,54.7409591674805,,,,,,,,,,,,,,,,
,3792812069.112,54.9955596923828,-4969.107421875,0.000108853192427928,9.84421754870244E-7,1,4.99626677034896,40.0298881530762,1.9983547485252,15.7200004905462,0.000592842417042321,0.000111311641889515,0.25,-3.84049976218766E-6,0.000106523193827671,7.78496499141716E-7,54.9954681396484,54.9954681396484,-4981.6201171875,-4956.5947265625,58.2915100786792,20.2836703085107,9.89999989542412E-6,0,0,0,200,54.8771171569824,1,6,14,2.22183227539062,55.2297172546387,,,,,,,,,,,,,,,,
,3792812119.1995,54.9946689605713,-4719.8095703125,0.000100831370679037,9.68733880403842E-7,1,4.99626677034896,40.0298881530762,1.99836519986181,15.7200004905462,0.000549533239126542,0.00010127488919642,0.25,-3.89845894129447E-6,9.8681140377084E-5,3.90521214445158E-7,54.9946823120117,54.9946823120117,-4732.5732421875,-4707.0458984375,58.3727994446793,20.2895774939964,9.89999989542412E-6,0,0,0,200,54.8820877075195,1,6,14,2.2198486328125,55.2297172546387,,,,,,,,,,,,,,,,
,3792812169.1,54.9952850341797,-4471.74267578125,9.26208958725768E-5,8.92034272449362E-7,1,4.99626677034896,40.0298881530762,1.99834577180245,15.7200004905462,0.000504405519322071,9.45642320277728E-5,0.25,-3.29788116789613E-6,9.06285937251145E-5,6.37589511836152E-7,54.9950485229492,54.9950485229492,-4484.1162109375,-4459.369140625,58.5900921730254,20.2840387237608,9.89999989542412E-6,0,0,0,200,54.8841285705566,1,6,14,2.22930908203125,54.2522010803223,,,,,,,,,,,,,,,,
,3792812219.1235,54.9959659576416,-4222.4443359375,8.40556351554723E-5,8.76469519341182E-7,1,4.99626677034896,40.0298881530762,1.99828731208986,15.7200004905462,0.000458068335058487,8.42624512250296E-5,0.25,-3.28179632152666E-6,8.22547732876931E-5,2.98397147839637E-7,54.9960708618164,54.9960708618164,-4234.60400390625,-4210.28466796875,58.6987385371985,20.2852121246238,9.89999989542412E-6,0,0,0,200,54.8831100463867,1,6,14,2.23159790039062,54.7409591674805,,,,,,,,,,,,,,,,
,3792812268.986,54.9958095550537,-3974.20825195313,7.59945582247311E-5,8.77108024918171E-7,1,4.99626677034896,40.0298881530762,1.99835641091601,15.7200004905462,0.000414587176086245,7.41383657945042E-5,0.25,-3.3468336178843E-6,7.43778359494115E-5,-9.93780379455803E-8,54.9955749511719,54.9955749511719,-3986.39819335937,-3962.01831054687,58.68701410941,20.2846274303908,9.89999989542412E-6,0,0,0,200,54.8847045898438,1,6,14,2.22946166992187,54.7409591674805,,,,,,,,,,,,,,,,
,3792812318.9395,54.9963455200195,-3725.30285644531,6.78235607407162E-5,8.60281644170472E-7,1,4.99626677034896,40.0298881530762,1.99818028015769,15.7200004905462,0.000369772060528349,6.69839935705715E-5,0.25,-2.83560547928194E-6,6.63705217418098E-5,6.07815225433224E-8,54.9966468811035,54.9966468811035,-3737.8017578125,-3712.80395507812,58.8816396106985,20.2836625292948,9.89999989542412E-6,0,0,0,200,54.8847312927246,1,6,14,2.2076416015625,55.2297172546387,,,,,,,,,,,,,,,,
,3792812368.9265,54.9961109161377,-3476.42065429687,6.00239652477185E-5,7.97858279373617E-7,1,4.99626677034896,40.0298881530762,1.99830431915034,15.7200004905462,0.000326956671708476,6.05863023534392E-5,0.25,-2.2693314686982E-6,5.87245711800239E-5,2.89819479500879E-7,54.996150970459,54.996150970459,-3488.65673828125,-3464.1845703125,58.7010834227562,20.2873002913645,9.89999989542412E-6,0,0,0,200,54.8891563415527,1,6,14,2.21908569335938,55.2297172546387,,,,,,,,,,,,,,,,
,3792812418.895,54.996150970459,-3227.640625,5.16086513650912E-5,8.37040591547766E-7,1,4.99626677034896,40.0298881530762,1.99822384669072,15.7200004905462,0.000281556875540495,5.00129507429253E-5,0.25,-2.33646718754511E-6,5.05046372836987E-5,-1.25953174050369E-7,54.9957313537598,54.9957313537598,-3239.79541015625,-3215.48583984375,58.6815427097754,20.2849718842403,9.89999989542412E-6,0,0,0,200,54.890697479248,1,6,14,2.20733642578125,54.7409591674805,,,,,,,,,,,,,,,,
,3792812468.796,54.9960842132568,-2979.10229492188,4.44629985262344E-5,8.46091849756648E-7,1,4.99626677034896,40.0298881530762,1.99826327123467,15.7200004905462,0.000242918151953852,4.1511498383291E-5,0.25,-2.30567995699711E-6,4.35216232273502E-5,-3.93375537594971E-7,54.9960441589355,54.9960441589355,-2991.88232421875,-2966.322265625,58.964492233737,20.2858513600944,9.89999989542412E-6,0,0,0,200,54.8918495178223,1,6,14,2.20855712890625,55.2297172546387,,,,,,,,,,,,,,,,
,3792812518.7575,54.997184753418,-2730.75439453125,3.70443294011331E-5,8.01974737546817E-7,1,4.99626677034896,40.0298881530762,1.99826047815121,15.7200004905462,0.000201515635813486,3.84122981913313E-5,0.25,-1.21276428072069E-6,3.6228459129861E-5,3.64726922894602E-7,54.9972496032715,54.9972496032715,-2743.2392578125,-2718.26953125,58.4275134410254,20.2841755352679,9.89999989542412E-6,0,0,0,200,54.8916931152344,1,6,14,2.23358154296875,54.7409591674805,,,,,,,,,,,,,,,,
,3792812568.7505,54.9962272644043,-2482.0302734375,2.91105387784048E-5,8.01378329895732E-7,1,4.99626677034896,40.0298881530762,1.99827347864229,15.7200004905462,0.000159351307859998,2.57259757824385E-5,0.25,-1.77929532298443E-6,2.8502365825732E-5,-5.19639411642782E-7,54.9962272644043,54.9962272644043,-2494.54077148438,-2469.51977539062,58.5080211785062,20.2829755344199,9.89999989542412E-6,0,0,0,200,54.8934478759766,1,6,14,2.2210693359375,54.7409591674805,,,,,,,,,,,,,,,,
,3792812618.824,54.9965839385986,-2232.29284667969,2.2898377278971E-5,8.12801263816142E-7,1,4.99626677034896,40.0298881530762,1.99829393514484,15.7200004905462,0.000125263985273854,2.05760200887941E-5,0.25,-1.3369824711076E-6,2.24161764084341E-5,-3.47095077759908E-7,54.996753692627,54.996753692627,-2244.79174804687,-2219.7939453125,58.6025982293331,20.2825018674508,9.89999989542412E-6,0,0,0,200,54.8942832946777,1,6,14,2.21878051757813,55.2297172546387,,,,,,,,,,,,,,,,
,3792812668.67,54.9966735839844,-1983.91711425781,1.52697632745921E-5,7.64401223589903E-7,1,4.99626677034896,40.0298881530762,1.99808602788824,15.7200004905462,8.36018051893792E-5,1.33526754872432E-5,0.25,-9.59749600210289E-7,1.49502827561668E-5,-2.97705741876802E-7,54.9970664978027,54.9970664978027,-1996.09301757813,-1971.7412109375,58.4650316099485,20.2810826772472,9.89999989542412E-6,0,0,0,200,54.8969535827637,1,6,14,2.2216796875,54.7409591674805,,,,,,,,,,,,,,,,
,3792812718.704,54.99680519104,-1735.48114013672,9.11464104736255E-6,7.99045392999266E-7,1,4.99626677034896,40.0298881530762,1.99831232432718,15.7200004905462,4.94536396877344E-5,9.98073333683152E-6,0.25,-2.00792653516446E-7,8.90789804263421E-6,1.85798226131664E-7,54.9967803955078,54.9967803955078,-1748.26806640625,-1722.69421386719,58.2125655982369,20.2829228356667,9.89999989542412E-6,0,0,0,200,54.8974800109863,1,6,14,2.22869873046875,54.7409591674805,,,,,,,,,,,,,,,,
,3792812768.69,54.9966354370117,-1486.62200927734,3.37247902200686E-6,6.73059064879681E-7,1,4.99626677034896,40.0298881530762,1.99821657260648,15.7200004905462,1.8779425048388E-5,1.54463105063168E-6,0.25,-4.72246969300638E-7,3.31249385143362E-6,-3.19728016065798E-7,54.996883392334,54.996883392334,-1499.0673828125,-1474.17663574219,58.6987385371985,20.284072345119,9.89999989542412E-6,0,0,0,200,54.8998336791992,1,6,14,2.21954345703125,54.7409591674805,,,,,,,,,,,,,,,,
,3792812818.613,54.996898651123,-1238.38342285156,-1.37130743605405E-6,8.5232700522522E-7,1,4.99626677034896,40.0298881530762,1.99825124785571,15.7200004905462,-6.96791476443731E-6,-3.59794086533098E-6,0.25,-3.58106091990831E-7,-1.32378767065171E-6,-4.07115356994382E-7,54.9967803955078,54.9967803955078,-1250.56860351562,-1226.1982421875,58.6252654563908,20.2815366776949,9.89999989542412E-6,0,0,0,200,54.9003829956055,1,6,14,2.22030639648438,54.7409591674805,,,,,,,,,,,,,,,,
,3792812868.5175,54.9969501495361,-990.037902832031,-6.15529144321511E-6,7.43194579590274E-7,1,4.99626677034896,40.0298881530762,1.99821691354664,15.7200004905462,-3.3293478679003E-5,-7.17083600535011E-6,0.25,5.5940107325376E-8,-6.01145080188587E-6,-2.03574738744642E-7,54.9970169067383,54.9970169067383,-1002.51116943359,-977.564636230469,58.832397013987,20.2831522356203,9.89999989542412E-6,0,0,0,200,54.9008026123047,1,6,14,2.21786499023438,54.7409591674805,,,,,,,,,,,,,,,,
,3792812918.5585,54.9974613189697,-740.944274902344,-9.55668698017229E-6,7.53031041291548E-7,1,4.99626677034896,40.0298881530762,1.99826488871896,15.7200004905462,-5.12880205855989E-5,-1.29216663870215E-5,0.25,-2.4431624550734E-7,-9.31904910873823E-6,-6.39508917530511E-7,54.9974098205566,54.9974098205566,-753.687072753906,-728.201477050781,58.4751927806985,20.2811060886275,9.89999989542412E-6,0,0,0,200,54.9023742675781,1,6,14,2.21923828125,54.7409591674805,,,,,,,,,,,,,,,,
,3792812968.4115,54.9967384338379,-492.770706176758,-1.07624422566369E-5,6.49601650998533E-7,1,4.99626677034896,40.0298881530762,1.99821586090077,15.7200004905462,-5.8134527143113E-5,-1.28642309019142E-5,0.25,3.75596158086976E-8,-1.05074866120036E-5,-4.15096146754545E-7,54.9966468811035,54.9966468811035,-505.220764160156,-480.320648193359,58.8214542147178,20.2805560502617,9.89999989542412E-6,0,0,0,200,54.9040222167969,1,6,14,2.22122192382813,55.2297172546387,,,,,,,,,,,,,,,,
,3792813018.394,54.9967670440674,-243.914024353027,-9.48582525968424E-6,6.69006627361586E-7,1,4.99626677034896,40.0298881530762,1.99838998018694,15.7200004905462,-5.19996239219014E-5,-7.96732034072045E-6,0.25,6.57878464074549E-7,-9.28699144544794E-6,2.43875228069616E-7,54.996753692627,54.996753692627,-256.712615966797,-231.115432739258,58.375144330237,20.285900494648,9.89999989542412E-6,0,0,0,200,54.9074249267578,1,6,14,2.21878051757813,54.7409591674805,,,,,,,,,,,,,,,,
,3792813068.412,54.9976711273193,5.20986866950989,-5.21418029245963E-6,6.97486777542918E-7,1,4.99626677034896,40.0298881530762,1.99828971572884,15.7200004905462,-2.8858929223079E-5,-3.14412844295758E-6,0.25,5.90507694375342E-7,-5.11436245314651E-6,3.5740963180165E-7,54.9976959228516,54.9976959228516,-7.00548124313354,17.4252185821533,58.4876988370062,20.2856549091796,9.89999989542412E-6,0,0,0,200,54.9066162109375,1,6,14,2.23175048828125,54.7409591674805,,,,,,,,,,,,,,,,
,3792813118.3425,54.9974994659424,253.44149017334,1.37367314012087E-6,8.75774919554885E-7,1,4.99626677034896,40.0298881530762,1.99826707848837,15.7200004905462,6.96352250605657E-6,3.67092807612014E-6,0.25,3.71116890866619E-7,1.32530009063746E-6,4.19935623689393E-7,54.9974594116211,54.9974594116211,240.982162475586,265.900817871094,58.63620825566,20.283455129174,9.89999989542412E-6,0,0,0,200,54.9069023132324,1,6,14,2.21817016601562,55.2297172546387,,,,,,,,,,,,,,,,
,3792813168.3635,54.9976177215576,502.119262695313,4.53935847339983E-6,7.77319206886676E-7,1,4.99626677034896,40.0298881530762,1.99829925054095,15.7200004905462,2.42501627849063E-5,6.62970927518853E-6,0.25,2.07156056730056E-7,4.42247647175727E-6,3.92756888257755E-7,54.9974594116211,54.9974594116211,489.662231445313,514.576293945313,58.5994717152562,20.2837227515863,9.89999989542412E-6,0,0,0,200,54.9070320129395,1,6,14,2.20626831054687,54.7409591674805,,,,,,,,,,,,,,,,
,3792813218.3335,54.9975395202637,750.989868164062,4.96612499202984E-6,8.11134917569137E-7,1,4.99626677034896,40.0298881530762,1.99834443120831,15.7200004905462,2.56391954722571E-5,1.12216218977065E-5,0.25,9.61834042297895E-7,4.80761451777288E-6,1.14732962145041E-6,54.9973297119141,54.9973297119141,738.45849609375,763.521240234375,58.6111961430447,20.2872668817385,9.89999989542412E-6,0,0,0,200,54.9086837768555,1,6,14,2.20657348632813,55.2297172546387,,,,,,,,,,,,,,,,
,3792813268.319,54.9973812103271,999.584045410156,2.45027386190946E-6,8.27256616995498E-7,1,4.99626677034896,40.0298881530762,1.99834239488884,15.7200004905462,1.26633080269325E-5,5.48185312110414E-6,0.25,4.64399756999707E-7,2.37260713619267E-6,5.56147145765608E-7,54.9975128173828,54.9975128173828,987.101501464844,1012.06658935547,58.8808579821793,20.2832837836461,9.89999989542412E-6,0,0,0,200,54.9102821350098,1,6,14,2.23190307617187,54.7409591674805,,,,,,,,,,,,,,,,
,3792813318.1875,54.9974994659424,1248.01086425781,-1.00548161225652E-6,4.2777510621607E-7,1,4.99626677034896,40.0298881530762,1.99844287284231,15.7200004905462,-6.78743674517801E-6,4.82248382728277E-6,0.25,1.11937862701006E-6,-1.02858438297766E-6,1.05069066519469E-6,54.9974594116211,54.9974594116211,1235.86059570312,1260.1611328125,58.42282366991,20.2834179044723,9.89999989542412E-6,0,0,0,200,54.9124031066895,1,6,14,2.22946166992187,54.7409591674805,,,,,,,,,,,,,,,,
,3792813368.186,54.9976043701172,1497.42059326172,-5.18250738597113E-6,6.73837697109969E-7,1,4.99626677034896,40.0298881530762,1.99837262082555,15.7200004905462,-2.93817849463757E-5,-5.67229539467172E-8,0.25,1.15488035764139E-6,-5.10833268608808E-6,9.10362024868427E-7,54.9975395202637,54.9975395202637,1485.25170898438,1509.58947753906,58.4087543565639,20.2820397949411,9.89999989542412E-6,0,0,0,200,54.9121932983398,1,6,14,2.22274780273438,54.7409591674805,,,,,,,,,,,,,,,,
,3792813418.2215,54.9975280761719,1746.68621826172,-1.12696930502179E-5,7.51122305846279E-7,1,4.99626677034896,40.0298881530762,1.99855717700576,15.7200004905462,-6.22091024933053E-5,-7.64901158252882E-6,0.25,1.11739331615426E-6,-1.10505160685683E-5,6.18898729814003E-7,54.9974098205566,54.9974098205566,1734.19665527344,1759.17578125,58.2813489079292,20.2824654978004,9.89999989542412E-6,0,0,0,200,54.9120330810547,1,6,14,2.20672607421875,54.7409591674805,,,,,,,,,,,,,,,,
,3792813468.153,54.9973182678223,1995.3662109375,-1.65873587178109E-5,7.20862867292584E-7,1,4.99626677034896,40.0298881530762,1.99846799391428,15.7200004905462,-9.11625357787094E-5,-1.30410252343529E-5,0.25,1.31414211870564E-6,-1.62517376532366E-5,5.88599426095421E-7,54.9972267150879,54.9972267150879,1982.9091796875,2007.8232421875,58.7362567061216,20.2824976909621,9.89999989542412E-6,0,0,0,200,54.9130020141602,1,6,14,2.2186279296875,55.2297172546387,,,,,,,,,,,,,,,,
,3792813518.027,54.9978408813477,2243.68835449219,-2.36178546917317E-5,7.67809823824527E-7,1,4.99626677034896,40.0298881530762,1.9984111759586,15.7200004905462,-0.000129452138290363,-2.01367412052147E-5,0.25,1.58026554543864E-6,-2.31290271798856E-5,5.54588601612607E-7,54.9977760314941,54.9977760314941,2231.18481445313,2256.19189453125,58.4290766980639,20.2825167154572,9.89999989542412E-6,0,0,0,200,54.914234161377,1,6,14,2.20504760742187,55.2297172546387,,,,,,,,,,,,,,,,
,3792813568.0635,54.9973812103271,2493.10290527344,-3.03485280148667E-5,7.7263139824486E-7,1,4.99626677034896,40.0298881530762,1.99848610958943,15.7200004905462,-0.000166393538129825,-2.57213927928635E-5,0.25,2.05888183036537E-6,-2.97231451447172E-5,7.40928504091054E-7,54.9975128173828,54.9975128173828,2480.62255859375,2505.58325195313,58.537723062237,20.282591773797,9.89999989542412E-6,0,0,0,200,54.9168510437012,1,6,14,2.21694946289062,55.2297172546387,,,,,,,,,,,,,,,,
,3792813618.0885,54.9972381591797,2741.96423339844,-3.81519147695841E-5,7.93114124132507E-7,1,4.99626677034896,40.0298881530762,1.99847774993114,15.7200004905462,-0.000208663466044244,-3.46697496965871E-5,0.25,2.1554068529603E-6,-3.73496494474181E-5,5.0958798507397E-7,54.9974098205566,54.9974098205566,2729.16333007813,2754.76513671875,58.7628320757754,20.284496704123,9.89999989542412E-6,0,0,0,200,54.9176139831543,1,6,14,2.2186279296875,54.7409591674805,,,,,,,,,,,,,,,,
,3792813668.006,54.9973831176758,2990.16101074219,-4.49145763315671E-5,8.19434207028442E-7,1,4.99626677034896,40.0298881530762,1.99823154234726,15.7200004905462,-0.000245131711165015,-4.30488858040544E-5,0.25,2.12231575309477E-6,-4.39551919376426E-5,1.95497381895877E-7,54.9972267150879,54.9972267150879,2977.34619140625,3002.97583007812,58.7690851039293,20.2834490812564,9.89999989542412E-6,0,0,0,200,54.9178199768066,1,6,14,2.21817016601562,55.2297172546387,,,,,,,,,,,,,,,,
,3792813717.982,54.9974746704102,3238.87133789063,-5.25965155825752E-5,8.09593393428442E-7,1,4.99626677034896,40.0298881530762,1.99849132838567,15.7200004905462,-0.000286982364182523,-5.09885182967036E-5,0.25,2.37898343203683E-6,-5.14715106957851E-5,1.26306210993789E-7,54.9975395202637,54.9975395202637,3226.63989257812,3251.10278320313,58.49395186516,20.2852837742755,9.89999989542412E-6,0,0,0,200,54.9199676513672,1,6,14,2.22015380859375,54.7409591674805,,,,,,,,,,,,,,,,
,3792813767.935,54.9976577758789,3487.59558105469,-6.05819580112684E-5,8.13735680053631E-7,1,4.99626677034896,40.0298881530762,1.99822067436913,15.7200004905462,-0.000330715683366478,-5.78920092917824E-5,0.25,2.89302549707558E-6,-5.92959370203689E-5,2.96210440126067E-7,54.9973564147949,54.9973564147949,3475.10131835937,3500.08984375,58.4853539514485,20.2837792542106,9.89999989542412E-6,0,0,0,200,54.919132232666,1,6,14,2.22030639648438,55.2297172546387,,,,,,,,,,,,,,,,
,3792813817.8235,54.9978141784668,3736.22448730469,-6.89833617264557E-5,8.95287996367124E-7,1,4.99626677034896,40.0298881530762,1.99840388088276,15.7200004905462,-0.000375817077205791,-6.95654398923361E-5,0.25,2.61955436152668E-6,-6.74947550617362E-5,-3.20100083184982E-7,54.9979591369629,54.9979591369629,3723.74877929687,3748.7001953125,58.5299067770447,20.2843958596379,9.89999989542412E-6,0,0,0,200,54.9206771850586,1,6,14,2.22061157226562,54.7409591674805,,,,,,,,,,,,,,,,
,3792813867.9535,54.9980373382568,3985.62255859375,-7.71800733686052E-5,9.02621018565725E-7,1,4.99626677034896,40.0298881530762,1.99841844338188,15.7200004905462,-0.000420136810777371,-7.94516419997328E-5,0.25,2.6299087263015E-6,-7.55065007074658E-5,-6.50244655063426E-7,54.9979591369629,54.9979591369629,3972.5078125,3998.7373046875,58.7237506498139,20.2838298002244,9.89999989542412E-6,0,0,0,200,54.9219856262207,1,6,14,2.22061157226562,54.7409591674805,,,,,,,,,,,,,,,,
,3792813917.7105,54.9976978302002,4233.5498046875,-8.4174807222913E-5,9.00879574008358E-7,1,4.99626677034896,40.0298881530762,1.99838178386593,15.7200004905462,-0.000458559267137159,-8.51963208055922E-5,0.25,3.13631590593306E-6,-8.23655628423135E-5,-4.45313658039914E-7,54.9976463317871,54.9976463317871,4221.09521484375,4246.00439453125,58.4705030095831,20.2818534349918,9.89999989542412E-6,0,0,0,200,54.9229278564453,1,6,14,2.21878051757813,54.7409591674805,,,,,,,,,,,,,,,,
,3792813967.769,54.9973964691162,4482.48071289063,-9.31013413041553E-5,1.00524445323232E-6,1,4.99626677034896,40.0298881530762,1.99835129272157,15.7200004905462,-0.000507321416678571,-9.37409817811962E-5,0.25,3.55807644379239E-6,-9.11093546124647E-5,-4.03180202666901E-7,54.9977760314941,54.9977760314941,4469.62646484375,4495.3349609375,58.801913501737,20.285374011509,9.89999989542412E-6,0,0,0,200,54.9233207702637,1,6,14,2.21832275390625,54.7409591674805,,,,,,,,,,,,,,,,
,3792814017.6985,54.9979858398438,4731.19140625,-0.00010133054071216,8.34167542981446E-7,1,4.99626677034896,40.0298881530762,1.99850176823513,15.7200004905462,-0.000552036035501509,-0.00010293518528327,0.25,3.7043447822435E-6,-9.91615364056415E-5,-6.00655484092682E-7,54.9978294372559,54.9978294372559,4718.74365234375,4743.63916015625,58.5166190922177,20.287217240254,9.89999989542412E-6,0,0,0,200,54.9247360229492,1,6,14,2.22137451171875,55.2297172546387,,,,,,,,,,,,,,,,
,3792814067.713,54.9983921051025,4979.82495117188,-0.000109175077968838,9.68271081192667E-7,1,4.99626677034896,40.0298881530762,1.99847322079059,15.7200004905462,-0.00059448990265873,-0.000112288611927118,0.25,3.732987793001E-6,-0.000106833967358213,-8.96644985236312E-7,54.9984321594238,54.9984321594238,4966.98193359375,4992.66796875,58.6674733964293,20.2850129099446,9.89999989542412E-6,0,0,0,200,54.924919128418,1,6,14,2.22213745117187,54.7409591674805,,,,,,,,,,,,,,,,
,3792814072.715,54.9983005523682,4996.31811523438,-0.000110044350007938,1.70589169675317E-6,1,4.99626677034896,40.0298881530762,1.99844324893733,15.7200004905462,-0.000599323289713341,-0.000112707621430628,0.25,3.85021433335059E-6,-0.000107688662598203,-8.18105763065352E-7,54.9983520507812,54.9983520507812,4992.66796875,4999.96826171875,58.6784161956985,20.2841371961782,9.89999989542412E-6,0,0,0,200,54.9249725341797,1,4,14,2.21725463867187,54.7409591674805,,,,,,,,,,,,,,,,